File: rheology/split_data/2023/P3-1 1.csv
Name:;;;P3-1 1
Number of Intervals:;;;1
Application:;;;RHEOPLUS/32 V3.61 21006227-33024
Device:;;;MCR302 SN81156610; FW3.65; Slot(9,-1)
Measuring Date/Time:;;;2023/09/19; 14:23
Measuring System:;;;CP50-2-SN42594; d=0.206 mm
Accessories:;;;TU1=P-PTD200-SN81263554

Interval:;;;1
Number of Data Points:;;;31

Time Setting:;;;31 Meas. Pts.
;;;Meas. Pt. Duration 60 ... 5 s log
Measuring Profile:
  Shear Rate;;;d(gamma)/dt = 0.01 ... 1000 1/s log; |Slope| = 6 Pt. / dec

Meas. Pts.;Shear Rate;Shear Stress;Viscosity;Speed;Torque;Status
;[1/s];[Pa];[Pa�Es];[1/min];[��Nm];[]
1;0.00999;0.0413;4.13;0.00333;1.35;Dy_auto
2;0.0147;0.0835;5.69;0.0049;2.74;Dy_auto
3;0.0215;0.164;7.63;0.00719;5.38;Dy_auto
4;0.0316;0.335;10.6;0.0105;11;Dy_auto
5;0.0464;0.588;12.7;0.0155;19.3;Dy_auto
6;0.0681;0.742;10.9;0.0227;24.3;Dy_auto
7;0.1;0.735;7.35;0.0334;24.1;Dy_auto
8;0.147;0.73;4.97;0.049;23.9;Dy_auto
9;0.215;0.79;3.67;0.0719;25.9;Dy_auto
10;0.316;0.867;2.74;0.106;28.4;Dy_auto
11;0.464;0.96;2.07;0.155;31.4;Dy_auto
12;0.681;1.04;1.53;0.227;34.2;Dy_auto
13;1;1.13;1.13;0.334;37.1;Dy_auto
14;1.47;1.22;0.832;0.49;40;Dy_auto
15;2.15;1.32;0.611;0.719;43.1;Dy_auto
16;3.16;1.42;0.448;1.06;46.4;Dy_auto
17;4.64;1.54;0.332;1.55;50.5;Dy_auto
18;6.81;1.69;0.247;2.27;55.2;Dy_auto
19;10;1.86;0.186;3.34;60.8;Dy_auto
20;14.7;2.07;0.141;4.9;68;Dy_auto
21;21.5;2.32;0.108;7.19;76;Dy_auto
22;31.6;2.63;0.0831;10.6;86.1;Dy_auto
23;46.4;2.99;0.0645;15.5;98.1;Dy_auto
24;68.1;3.43;0.0503;22.7;112;Dy_auto
25;100;3.97;0.0397;33.4;130;Dy_auto
26;147;4.6;0.0313;49;151;Dy_auto
27;215;5.42;0.0252;71.9;178;Dy_auto
28;316;6.48;0.0205;106;212;Dy_auto
29;464;7.85;0.0169;155;257;Dy_auto
30;681;9.62;0.0141;227;315;Dy_auto
31;1000;11.9;0.0119;334;389;Dy_auto