File: rheology/input_data/20230919_cnf_FlowCurve Data_20230919225608.csv
Data Series Information
Name:;;;P3-1 1
Number of Intervals:;;;1
Application:;;;RHEOPLUS/32 V3.61 21006227-33024
Device:;;;MCR302 SN81156610; FW3.65; Slot(9,-1)
Measuring Date/Time:;;;2023/09/19; 14:23
Measuring System:;;;CP50-2-SN42594; d=0.206 mm
Accessories:;;;TU1=P-PTD200-SN81263554

Interval:;;;1
Number of Data Points:;;;31

Time Setting:;;;31 Meas. Pts.
;;;Meas. Pt. Duration 60 ... 5 s log
Measuring Profile:
  Shear Rate;;;d(gamma)/dt = 0.01 ... 1000 1/s log; |Slope| = 6 Pt. / dec

Meas. Pts.;Shear Rate;Shear Stress;Viscosity;Speed;Torque;Status
;[1/s];[Pa];[Pa�Es];[1/min];[��Nm];[]
1;0.00999;0.0413;4.13;0.00333;1.35;Dy_auto
2;0.0147;0.0835;5.69;0.0049;2.74;Dy_auto
3;0.0215;0.164;7.63;0.00719;5.38;Dy_auto
4;0.0316;0.335;10.6;0.0105;11;Dy_auto
5;0.0464;0.588;12.7;0.0155;19.3;Dy_auto
6;0.0681;0.742;10.9;0.0227;24.3;Dy_auto
7;0.1;0.735;7.35;0.0334;24.1;Dy_auto
8;0.147;0.73;4.97;0.049;23.9;Dy_auto
9;0.215;0.79;3.67;0.0719;25.9;Dy_auto
10;0.316;0.867;2.74;0.106;28.4;Dy_auto
11;0.464;0.96;2.07;0.155;31.4;Dy_auto
12;0.681;1.04;1.53;0.227;34.2;Dy_auto
13;1;1.13;1.13;0.334;37.1;Dy_auto
14;1.47;1.22;0.832;0.49;40;Dy_auto
15;2.15;1.32;0.611;0.719;43.1;Dy_auto
16;3.16;1.42;0.448;1.06;46.4;Dy_auto
17;4.64;1.54;0.332;1.55;50.5;Dy_auto
18;6.81;1.69;0.247;2.27;55.2;Dy_auto
19;10;1.86;0.186;3.34;60.8;Dy_auto
20;14.7;2.07;0.141;4.9;68;Dy_auto
21;21.5;2.32;0.108;7.19;76;Dy_auto
22;31.6;2.63;0.0831;10.6;86.1;Dy_auto
23;46.4;2.99;0.0645;15.5;98.1;Dy_auto
24;68.1;3.43;0.0503;22.7;112;Dy_auto
25;100;3.97;0.0397;33.4;130;Dy_auto
26;147;4.6;0.0313;49;151;Dy_auto
27;215;5.42;0.0252;71.9;178;Dy_auto
28;316;6.48;0.0205;106;212;Dy_auto
29;464;7.85;0.0169;155;257;Dy_auto
30;681;9.62;0.0141;227;315;Dy_auto
31;1000;11.9;0.0119;334;389;Dy_auto

Data Series Information
Name:;;;P3-1 2
Number of Intervals:;;;1
Application:;;;RHEOPLUS/32 V3.61 21006227-33024
Device:;;;MCR302 SN81156610; FW3.65; Slot(9,-1)
Measuring Date/Time:;;;2023/09/19; 14:36
Measuring System:;;;CP50-2-SN42594; d=0.206 mm
Accessories:;;;TU1=P-PTD200-SN81263554

Interval:;;;1
Number of Data Points:;;;31

Time Setting:;;;31 Meas. Pts.
;;;Meas. Pt. Duration 60 ... 5 s log
Measuring Profile:
  Shear Rate;;;d(gamma)/dt = 0.01 ... 1000 1/s log; |Slope| = 6 Pt. / dec

Meas. Pts.;Shear Rate;Shear Stress;Viscosity;Speed;Torque;Status
;[1/s];[Pa];[Pa�Es];[1/min];[��Nm];[]
1;0.01;0.0125;1.25;0.00334;0.41;Dy_auto
2;0.0147;0.0217;1.48;0.0049;0.711;Dy_auto
3;0.0215;0.0369;1.71;0.00719;1.21;Dy_auto
4;0.0316;0.0665;2.1;0.0106;2.18;Dy_auto
5;0.0464;0.117;2.52;0.0155;3.83;Dy_auto
6;0.0681;0.158;2.33;0.0227;5.19;Dy_auto
7;0.1;0.182;1.82;0.0334;5.97;Dy_auto
8;0.147;0.198;1.35;0.049;6.49;Dy_auto
9;0.215;0.217;1.01;0.0719;7.1;Dy_auto
10;0.316;0.251;0.794;0.106;8.22;Dy_auto
11;0.464;0.301;0.65;0.155;9.88;Dy_auto
12;0.681;0.36;0.529;0.227;11.8;Dy_auto
13;1;0.426;0.426;0.334;14;Dy_auto
14;1.47;0.51;0.347;0.49;16.7;Dy_auto
15;2.15;0.606;0.281;0.719;19.9;Dy_auto
16;3.16;0.719;0.227;1.06;23.5;Dy_auto
17;4.64;0.85;0.183;1.55;27.9;Dy_auto
18;6.81;1.01;0.148;2.27;33;Dy_auto
19;10;1.19;0.119;3.34;38.9;Dy_auto
20;14.7;1.4;0.0954;4.9;45.9;Dy_auto
21;21.5;1.67;0.0773;7.19;54.6;Dy_auto
22;31.6;1.98;0.0626;10.6;64.8;Dy_auto
23;46.4;2.36;0.0508;15.5;77.3;Dy_auto
24;68.1;2.83;0.0415;22.7;92.6;Dy_auto
25;100;3.4;0.034;33.4;111;Dy_auto
26;147;4.12;0.0281;49;135;Dy_auto
27;215;5.02;0.0233;71.9;164;Dy_auto
28;316;6.15;0.0195;106;202;Dy_auto
29;464;7.58;0.0163;155;248;Dy_auto
30;681;9.39;0.0138;227;308;Dy_auto
31;1000;11.7;0.0117;334;383;Dy_auto

Data Series Information
Name:;;;P3-1 3
Number of Intervals:;;;1
Application:;;;RHEOPLUS/32 V3.61 21006227-33024
Device:;;;MCR302 SN81156610; FW3.65; Slot(9,-1)
Measuring Date/Time:;;;2023/09/19; 14:48
Measuring System:;;;CP50-2-SN42594; d=0.206 mm
Accessories:;;;TU1=P-PTD200-SN81263554

Interval:;;;1
Number of Data Points:;;;31

Time Setting:;;;31 Meas. Pts.
;;;Meas. Pt. Duration 60 ... 5 s log
Measuring Profile:
  Shear Rate;;;d(gamma)/dt = 0.01 ... 1000 1/s log; |Slope| = 6 Pt. / dec

Meas. Pts.;Shear Rate;Shear Stress;Viscosity;Speed;Torque;Status
;[1/s];[Pa];[Pa�Es];[1/min];[��Nm];[]
1;0.01;0.01;1;0.00334;0.329;Dy_auto
2;0.0147;0.0163;1.11;0.0049;0.535;Dy_auto
3;0.0215;0.0266;1.24;0.00719;0.872;Dy_auto
4;0.0316;0.0441;1.39;0.0106;1.45;Dy_auto
5;0.0464;0.0723;1.56;0.0155;2.37;Dy_auto
6;0.0681;0.102;1.5;0.0227;3.35;Dy_auto
7;0.1;0.125;1.25;0.0334;4.11;Dy_auto
8;0.147;0.147;1;0.049;4.83;Dy_auto
9;0.215;0.171;0.793;0.0719;5.6;Dy_auto
10;0.316;0.204;0.647;0.106;6.7;Dy_auto
11;0.464;0.25;0.539;0.155;8.2;Dy_auto
12;0.681;0.305;0.448;0.227;10;Dy_auto
13;1;0.369;0.369;0.334;12.1;Dy_auto
14;1.47;0.447;0.305;0.49;14.7;Dy_auto
15;2.15;0.54;0.251;0.719;17.7;Dy_auto
16;3.16;0.648;0.205;1.06;21.2;Dy_auto
17;4.64;0.776;0.167;1.55;25.4;Dy_auto
18;6.81;0.927;0.136;2.27;30.4;Dy_auto
19;10;1.1;0.11;3.34;36.1;Dy_auto
20;14.7;1.32;0.0896;4.9;43.1;Dy_auto
21;21.5;1.57;0.0729;7.19;51.5;Dy_auto
22;31.6;1.89;0.0596;10.6;61.8;Dy_auto
23;46.4;2.26;0.0487;15.5;74.1;Dy_auto
24;68.1;2.72;0.04;22.7;89.2;Dy_auto
25;100;3.29;0.0329;33.4;108;Dy_auto
26;147;4;0.0273;49;131;Dy_auto
27;215;4.9;0.0227;71.9;160;Dy_auto
28;316;6.02;0.019;106;197;Dy_auto
29;464;7.44;0.016;155;244;Dy_auto
30;681;9.26;0.0136;227;303;Dy_auto
31;1000;11.6;0.0116;334;379;Dy_auto

Data Series Information
Name:;;;P3-1 4
Number of Intervals:;;;1
Application:;;;RHEOPLUS/32 V3.61 21006227-33024
Device:;;;MCR302 SN81156610; FW3.65; Slot(9,-1)
Measuring Date/Time:;;;2023/09/19; 15:01
Measuring System:;;;CP50-2-SN42594; d=0.206 mm
Accessories:;;;TU1=P-PTD200-SN81263554

Interval:;;;1
Number of Data Points:;;;31

Time Setting:;;;31 Meas. Pts.
;;;Meas. Pt. Duration 60 ... 5 s log
Measuring Profile:
  Shear Rate;;;d(gamma)/dt = 0.01 ... 1000 1/s log; |Slope| = 6 Pt. / dec

Meas. Pts.;Shear Rate;Shear Stress;Viscosity;Speed;Torque;Status
;[1/s];[Pa];[Pa�Es];[1/min];[��Nm];[]
1;0.01;0.00934;0.933;0.00334;0.306;Dy_auto
2;0.0147;0.0162;1.1;0.0049;0.532;Dy_auto
3;0.0215;0.0239;1.11;0.00719;0.784;Dy_auto
4;0.0316;0.0385;1.22;0.0106;1.26;Dy_auto
5;0.0464;0.0598;1.29;0.0155;1.96;Dy_auto
6;0.0681;0.0834;1.22;0.0227;2.73;Dy_auto
7;0.1;0.106;1.06;0.0334;3.49;Dy_auto
8;0.147;0.127;0.868;0.049;4.17;Dy_auto
9;0.215;0.152;0.707;0.0719;4.99;Dy_auto
10;0.316;0.185;0.586;0.106;6.07;Dy_auto
11;0.464;0.228;0.492;0.155;7.49;Dy_auto
12;0.681;0.282;0.413;0.227;9.22;Dy_auto
13;1;0.343;0.343;0.334;11.2;Dy_auto
14;1.47;0.418;0.285;0.49;13.7;Dy_auto
15;2.15;0.508;0.236;0.719;16.6;Dy_auto
16;3.16;0.613;0.194;1.06;20.1;Dy_auto
17;4.64;0.739;0.159;1.55;24.2;Dy_auto
18;6.81;0.887;0.13;2.27;29.1;Dy_auto
19;10;1.06;0.106;3.34;34.9;Dy_auto
20;14.7;1.27;0.0867;4.9;41.7;Dy_auto
21;21.5;1.53;0.0708;7.19;50;Dy_auto
22;31.6;1.83;0.058;10.6;60.1;Dy_auto
23;46.4;2.2;0.0475;15.5;72.2;Dy_auto
24;68.1;2.66;0.0391;22.7;87.2;Dy_auto
25;100;3.22;0.0322;33.4;106;Dy_auto
26;147;3.93;0.0268;49;129;Dy_auto
27;215;4.81;0.0223;71.9;158;Dy_auto
28;316;5.93;0.0187;106;194;Dy_auto
29;464;7.34;0.0158;155;240;Dy_auto
30;681;9.15;0.0134;227;300;Dy_auto
31;1000;11.5;0.0115;334;376;Dy_auto

Data Series Information
Name:;;;P3-1 5
Number of Intervals:;;;1
Application:;;;RHEOPLUS/32 V3.61 21006227-33024
Device:;;;MCR302 SN81156610; FW3.65; Slot(9,-1)
Measuring Date/Time:;;;2023/09/19; 15:13
Measuring System:;;;CP50-2-SN42594; d=0.206 mm
Accessories:;;;TU1=P-PTD200-SN81263554

Interval:;;;1
Number of Data Points:;;;1

Time Setting:;;;31 Meas. Pts.
;;;Meas. Pt. Duration 60 ... 5 s log
Measuring Profile:
  Shear Rate;;;d(gamma)/dt = 0.01 ... 1000 1/s log; |Slope| = 6 Pt. / dec

Meas. Pts.;Shear Rate;Shear Stress;Viscosity;Speed;Torque;Status
;[1/s];[Pa];[Pa�Es];[1/min];[��Nm];[]
1;0.01;0.00666;0.667;0.00334;0.218;Dy_auto

Data Series Information
Name:;;;P3-1 6
Number of Intervals:;;;1
Application:;;;RHEOPLUS/32 V3.61 21006227-33024
Device:;;;MCR302 SN81156610; FW3.65; Slot(9,-1)
Measuring Date/Time:;;;2023/09/19; 15:15
Measuring System:;;;CP50-2-SN42594; d=0.206 mm
Accessories:;;;TU1=P-PTD200-SN81263554

Interval:;;;1
Number of Data Points:;;;31

Time Setting:;;;31 Meas. Pts.
;;;Meas. Pt. Duration 60 ... 5 s log
Measuring Profile:
  Shear Rate;;;d(gamma)/dt = 0.01 ... 1000 1/s log; |Slope| = 6 Pt. / dec

Meas. Pts.;Shear Rate;Shear Stress;Viscosity;Speed;Torque;Status
;[1/s];[Pa];[Pa�Es];[1/min];[��Nm];[]
1;0.01;0.00868;0.869;0.00334;0.285;Dy_auto
2;0.0147;0.0159;1.08;0.0049;0.52;Dy_auto
3;0.0215;0.0278;1.29;0.00719;0.91;Dy_auto
4;0.0316;0.0464;1.47;0.0106;1.52;Dy_auto
5;0.0464;0.0716;1.54;0.0155;2.34;Dy_auto
6;0.0681;0.0945;1.39;0.0227;3.1;Dy_auto
7;0.1;0.113;1.13;0.0334;3.69;Dy_auto
8;0.147;0.131;0.891;0.049;4.29;Dy_auto
9;0.215;0.154;0.717;0.0719;5.06;Dy_auto
10;0.316;0.187;0.593;0.106;6.14;Dy_auto
11;0.464;0.231;0.497;0.155;7.56;Dy_auto
12;0.681;0.283;0.415;0.227;9.27;Dy_auto
13;1;0.344;0.344;0.334;11.3;Dy_auto
14;1.47;0.418;0.285;0.49;13.7;Dy_auto
15;2.15;0.507;0.235;0.719;16.6;Dy_auto
16;3.16;0.612;0.194;1.06;20;Dy_auto
17;4.64;0.736;0.159;1.55;24.1;Dy_auto
18;6.81;0.882;0.129;2.27;28.9;Dy_auto
19;10;1.06;0.106;3.34;34.7;Dy_auto
20;14.7;1.27;0.0863;4.9;41.5;Dy_auto
21;21.5;1.51;0.0701;7.19;49.5;Dy_auto
22;31.6;1.82;0.0576;10.6;59.7;Dy_auto
23;46.4;2.19;0.0472;15.5;71.8;Dy_auto
24;68.1;2.64;0.0388;22.7;86.6;Dy_auto
25;100;3.2;0.032;33.4;105;Dy_auto
26;147;3.9;0.0266;49;128;Dy_auto
27;215;4.78;0.0222;71.9;157;Dy_auto
28;316;5.88;0.0186;106;193;Dy_auto
29;464;7.29;0.0157;155;239;Dy_auto
30;681;9.07;0.0133;227;297;Dy_auto
31;1000;11.4;0.0114;334;373;Dy_auto

Data Series Information
Name:;;;P3-1 7
Number of Intervals:;;;1
Application:;;;RHEOPLUS/32 V3.61 21006227-33024
Device:;;;MCR302 SN81156610; FW3.65; Slot(9,-1)
Measuring Date/Time:;;;2023/09/19; 15:29
Measuring System:;;;CP50-2-SN42594; d=0.206 mm
Accessories:;;;TU1=P-PTD200-SN81263554

Interval:;;;1
Number of Data Points:;;;31

Time Setting:;;;31 Meas. Pts.
;;;Meas. Pt. Duration 60 ... 5 s log
Measuring Profile:
  Shear Rate;;;d(gamma)/dt = 0.01 ... 1000 1/s log; |Slope| = 6 Pt. / dec

Meas. Pts.;Shear Rate;Shear Stress;Viscosity;Speed;Torque;Status
;[1/s];[Pa];[Pa�Es];[1/min];[��Nm];[]
1;0.01;0.0108;1.08;0.00334;0.355;Dy_auto
2;0.0147;0.016;1.09;0.0049;0.526;Dy_auto
3;0.0215;0.0247;1.15;0.00719;0.81;Dy_auto
4;0.0316;0.0388;1.23;0.0106;1.27;Dy_auto
5;0.0464;0.0576;1.24;0.0155;1.89;Dy_auto
6;0.0681;0.0781;1.15;0.0227;2.56;Dy_auto
7;0.1;0.0971;0.971;0.0334;3.18;Dy_auto
8;0.147;0.117;0.8;0.049;3.85;Dy_auto
9;0.215;0.142;0.66;0.0719;4.66;Dy_auto
10;0.316;0.174;0.55;0.106;5.7;Dy_auto
11;0.464;0.215;0.464;0.155;7.06;Dy_auto
12;0.681;0.266;0.39;0.227;8.7;Dy_auto
13;1;0.325;0.325;0.334;10.7;Dy_auto
14;1.47;0.398;0.271;0.49;13.1;Dy_auto
15;2.15;0.486;0.225;0.719;15.9;Dy_auto
16;3.16;0.589;0.186;1.06;19.3;Dy_auto
17;4.64;0.711;0.153;1.55;23.3;Dy_auto
18;6.81;0.856;0.126;2.27;28.1;Dy_auto
19;10;1.03;0.103;3.34;33.7;Dy_auto
20;14.7;1.23;0.084;4.9;40.4;Dy_auto
21;21.5;1.48;0.0689;7.19;48.6;Dy_auto
22;31.6;1.79;0.0565;10.6;58.5;Dy_auto
23;46.4;2.15;0.0464;15.5;70.5;Dy_auto
24;68.1;2.6;0.0382;22.7;85.3;Dy_auto
25;100;3.16;0.0316;33.4;103;Dy_auto
26;147;3.85;0.0262;49;126;Dy_auto
27;215;4.72;0.0219;71.9;155;Dy_auto
28;316;5.82;0.0184;106;191;Dy_auto
29;464;7.22;0.0155;155;236;Dy_auto
30;681;9.01;0.0132;227;295;Dy_auto
31;1000;11.3;0.0113;334;370;Dy_auto

Data Series Information
Name:;;;P3-2 1
Number of Intervals:;;;1
Application:;;;RHEOPLUS/32 V3.61 21006227-33024
Device:;;;MCR302 SN81156610; FW3.65; Slot(9,-1)
Measuring Date/Time:;;;2023/09/19; 15:44
Measuring System:;;;CP50-2-SN42594; d=0.206 mm
Accessories:;;;TU1=P-PTD200-SN81263554

Interval:;;;1
Number of Data Points:;;;31

Time Setting:;;;31 Meas. Pts.
;;;Meas. Pt. Duration 60 ... 5 s log
Measuring Profile:
  Shear Rate;;;d(gamma)/dt = 0.01 ... 1000 1/s log; |Slope| = 6 Pt. / dec

Meas. Pts.;Shear Rate;Shear Stress;Viscosity;Speed;Torque;Status
;[1/s];[Pa];[Pa�Es];[1/min];[��Nm];[]
1;0.01;0.0392;3.92;0.00334;1.28;Dy_auto
2;0.0147;0.0823;5.61;0.0049;2.7;Dy_auto
3;0.0215;0.151;7;0.00719;4.94;Dy_auto
4;0.0316;0.274;8.68;0.0105;8.99;Dy_auto
5;0.0464;0.464;10;0.0155;15.2;Dy_auto
6;0.0681;0.609;8.95;0.0227;20;Dy_auto
7;0.1;0.644;6.44;0.0334;21.1;Dy_auto
8;0.147;0.663;4.51;0.049;21.7;Dy_auto
9;0.215;0.711;3.3;0.0719;23.3;Dy_auto
10;0.316;0.775;2.45;0.106;25.4;Dy_auto
11;0.464;0.838;1.8;0.155;27.4;Dy_auto
12;0.681;0.904;1.33;0.227;29.6;Dy_auto
13;1;0.98;0.979;0.334;32.1;Dy_auto
14;1.47;1.05;0.715;0.49;34.4;Dy_auto
15;2.15;1.13;0.524;0.719;37;Dy_auto
16;3.16;1.23;0.388;1.06;40.2;Dy_auto
17;4.64;1.34;0.288;1.55;43.8;Dy_auto
18;6.81;1.47;0.216;2.27;48.2;Dy_auto
19;10;1.63;0.163;3.34;53.5;Dy_auto
20;14.7;1.83;0.125;4.9;60;Dy_auto
21;21.5;2.07;0.0963;7.19;68;Dy_auto
22;31.6;2.36;0.0747;10.6;77.4;Dy_auto
23;46.4;2.71;0.0583;15.5;88.7;Dy_auto
24;68.1;3.13;0.046;22.7;103;Dy_auto
25;100;3.65;0.0365;33.4;120;Dy_auto
26;147;4.31;0.0294;49;141;Dy_auto
27;215;5.16;0.0239;71.9;169;Dy_auto
28;316;6.23;0.0197;106;204;Dy_auto
29;464;7.6;0.0164;155;249;Dy_auto
30;681;9.35;0.0137;227;306;Dy_auto
31;1000;11.6;0.0116;334;379;Dy_auto

Data Series Information
Name:;;;P3-2 2
Number of Intervals:;;;1
Application:;;;RHEOPLUS/32 V3.61 21006227-33024
Device:;;;MCR302 SN81156610; FW3.65; Slot(9,-1)
Measuring Date/Time:;;;2023/09/19; 15:58
Measuring System:;;;CP50-2-SN42594; d=0.206 mm
Accessories:;;;TU1=P-PTD200-SN81263554

Interval:;;;1
Number of Data Points:;;;31

Time Setting:;;;31 Meas. Pts.
;;;Meas. Pt. Duration 60 ... 5 s log
Measuring Profile:
  Shear Rate;;;d(gamma)/dt = 0.01 ... 1000 1/s log; |Slope| = 6 Pt. / dec

Meas. Pts.;Shear Rate;Shear Stress;Viscosity;Speed;Torque;Status
;[1/s];[Pa];[Pa�Es];[1/min];[��Nm];[]
1;0.01;0.011;1.1;0.00334;0.359;Dy_auto
2;0.0147;0.02;1.37;0.0049;0.657;Dy_auto
3;0.0215;0.0339;1.57;0.00719;1.11;Dy_auto
4;0.0316;0.0619;1.96;0.0106;2.03;Dy_auto
5;0.0464;0.111;2.39;0.0155;3.63;Dy_auto
6;0.0681;0.147;2.16;0.0227;4.82;Dy_auto
7;0.1;0.162;1.62;0.0334;5.31;Dy_auto
8;0.147;0.173;1.18;0.049;5.68;Dy_auto
9;0.215;0.193;0.895;0.0719;6.32;Dy_auto
10;0.316;0.223;0.704;0.106;7.3;Dy_auto
11;0.464;0.269;0.579;0.155;8.81;Dy_auto
12;0.681;0.324;0.476;0.227;10.6;Dy_auto
13;1;0.386;0.386;0.334;12.7;Dy_auto
14;1.47;0.462;0.315;0.49;15.1;Dy_auto
15;2.15;0.556;0.258;0.719;18.2;Dy_auto
16;3.16;0.665;0.21;1.06;21.8;Dy_auto
17;4.64;0.789;0.17;1.55;25.8;Dy_auto
18;6.81;0.937;0.138;2.27;30.7;Dy_auto
19;10;1.11;0.111;3.34;36.5;Dy_auto
20;14.7;1.32;0.0902;4.9;43.4;Dy_auto
21;21.5;1.57;0.0727;7.19;51.3;Dy_auto
22;31.6;1.88;0.0594;10.6;61.5;Dy_auto
23;46.4;2.25;0.0484;15.5;73.6;Dy_auto
24;68.1;2.7;0.0397;22.7;88.5;Dy_auto
25;100;3.26;0.0326;33.4;107;Dy_auto
26;147;3.97;0.027;49;130;Dy_auto
27;215;4.84;0.0225;71.9;159;Dy_auto
28;316;5.95;0.0188;106;195;Dy_auto
29;464;7.35;0.0158;155;241;Dy_auto
30;681;9.13;0.0134;227;299;Dy_auto
31;1000;11.4;0.0114;334;374;Dy_auto

Data Series Information
Name:;;;P3-2 3
Number of Intervals:;;;1
Application:;;;RHEOPLUS/32 V3.61 21006227-33024
Device:;;;MCR302 SN81156610; FW3.65; Slot(9,-1)
Measuring Date/Time:;;;2023/09/19; 16:12
Measuring System:;;;CP50-2-SN42594; d=0.206 mm
Accessories:;;;TU1=P-PTD200-SN81263554

Interval:;;;1
Number of Data Points:;;;31

Time Setting:;;;31 Meas. Pts.
;;;Meas. Pt. Duration 60 ... 5 s log
Measuring Profile:
  Shear Rate;;;d(gamma)/dt = 0.01 ... 1000 1/s log; |Slope| = 6 Pt. / dec

Meas. Pts.;Shear Rate;Shear Stress;Viscosity;Speed;Torque;Status
;[1/s];[Pa];[Pa�Es];[1/min];[��Nm];[]
1;0.01;0.00975;0.975;0.00334;0.319;Dy_auto
2;0.0147;0.0165;1.13;0.0049;0.542;Dy_auto
3;0.0215;0.0273;1.27;0.00719;0.896;Dy_auto
4;0.0316;0.0451;1.43;0.0106;1.48;Dy_auto
5;0.0464;0.0698;1.5;0.0155;2.29;Dy_auto
6;0.0681;0.0938;1.38;0.0227;3.07;Dy_auto
7;0.1;0.112;1.12;0.0334;3.66;Dy_auto
8;0.147;0.131;0.89;0.049;4.28;Dy_auto
9;0.215;0.154;0.715;0.0719;5.05;Dy_auto
10;0.316;0.187;0.593;0.106;6.14;Dy_auto
11;0.464;0.23;0.496;0.155;7.54;Dy_auto
12;0.681;0.281;0.413;0.227;9.21;Dy_auto
13;1;0.341;0.341;0.334;11.2;Dy_auto
14;1.47;0.416;0.283;0.49;13.6;Dy_auto
15;2.15;0.502;0.233;0.719;16.4;Dy_auto
16;3.16;0.604;0.191;1.06;19.8;Dy_auto
17;4.64;0.727;0.157;1.55;23.8;Dy_auto
18;6.81;0.871;0.128;2.27;28.5;Dy_auto
19;10;1.04;0.104;3.34;34.2;Dy_auto
20;14.7;1.25;0.0849;4.9;40.8;Dy_auto
21;21.5;1.49;0.0694;7.19;49;Dy_auto
22;31.6;1.8;0.0568;10.6;58.8;Dy_auto
23;46.4;2.16;0.0465;15.5;70.8;Dy_auto
24;68.1;2.61;0.0383;22.7;85.5;Dy_auto
25;100;3.16;0.0316;33.4;104;Dy_auto
26;147;3.86;0.0263;49;126;Dy_auto
27;215;4.73;0.0219;71.9;155;Dy_auto
28;316;5.83;0.0184;106;191;Dy_auto
29;464;7.22;0.0156;155;237;Dy_auto
30;681;9.01;0.0132;227;295;Dy_auto
31;1000;11.3;0.0113;334;369;Dy_auto

Data Series Information
Name:;;;P3-2 4
Number of Intervals:;;;1
Application:;;;RHEOPLUS/32 V3.61 21006227-33024
Device:;;;MCR302 SN81156610; FW3.65; Slot(9,-1)
Measuring Date/Time:;;;2023/09/19; 16:28
Measuring System:;;;CP50-2-SN42594; d=0.206 mm
Accessories:;;;TU1=P-PTD200-SN81263554

Interval:;;;1
Number of Data Points:;;;1

Time Setting:;;;31 Meas. Pts.
;;;Meas. Pt. Duration 60 ... 5 s log
Measuring Profile:
  Shear Rate;;;d(gamma)/dt = 0.01 ... 1000 1/s log; |Slope| = 6 Pt. / dec

Meas. Pts.;Shear Rate;Shear Stress;Viscosity;Speed;Torque;Status
;[1/s];[Pa];[Pa�Es];[1/min];[��Nm];[]
1;0.01;0.00416;0.416;0.00334;0.136;Dy_auto

Data Series Information
Name:;;;P3-2 5
Number of Intervals:;;;1
Application:;;;RHEOPLUS/32 V3.61 21006227-33024
Device:;;;MCR302 SN81156610; FW3.65; Slot(9,-1)
Measuring Date/Time:;;;2023/09/19; 16:30
Measuring System:;;;CP50-2-SN42594; d=0.206 mm
Accessories:;;;TU1=P-PTD200-SN81263554

Interval:;;;1
Number of Data Points:;;;1

Time Setting:;;;31 Meas. Pts.
;;;Meas. Pt. Duration 60 ... 5 s log
Measuring Profile:
  Shear Rate;;;d(gamma)/dt = 0.01 ... 1000 1/s log; |Slope| = 6 Pt. / dec

Meas. Pts.;Shear Rate;Shear Stress;Viscosity;Speed;Torque;Status
;[1/s];[Pa];[Pa�Es];[1/min];[��Nm];[]
1;0.01;0.00505;0.505;0.00334;0.165;Dy_auto

Data Series Information
Name:;;;P3-2 6
Number of Intervals:;;;1
Application:;;;RHEOPLUS/32 V3.61 21006227-33024
Device:;;;MCR302 SN81156610; FW3.65; Slot(9,-1)
Measuring Date/Time:;;;2023/09/19; 16:32
Measuring System:;;;CP50-2-SN42594; d=0.206 mm
Accessories:;;;TU1=P-PTD200-SN81263554

Interval:;;;1
Number of Data Points:;;;31

Time Setting:;;;31 Meas. Pts.
;;;Meas. Pt. Duration 60 ... 5 s log
Measuring Profile:
  Shear Rate;;;d(gamma)/dt = 0.01 ... 1000 1/s log; |Slope| = 6 Pt. / dec

Meas. Pts.;Shear Rate;Shear Stress;Viscosity;Speed;Torque;Status
;[1/s];[Pa];[Pa�Es];[1/min];[��Nm];[]
1;0.01;0.00591;0.591;0.00334;0.193;Dy_auto
2;0.0147;0.0163;1.11;0.0049;0.533;Dy_auto
3;0.0215;0.0302;1.4;0.00719;0.988;Dy_auto
4;0.0316;0.0565;1.79;0.0106;1.85;Dy_auto
5;0.0464;0.099;2.13;0.0155;3.25;Dy_auto
6;0.0681;0.127;1.86;0.0227;4.16;Dy_auto
7;0.1;0.138;1.38;0.0334;4.51;Dy_auto
8;0.147;0.148;1.01;0.049;4.83;Dy_auto
9;0.215;0.167;0.777;0.0719;5.49;Dy_auto
10;0.316;0.199;0.629;0.106;6.52;Dy_auto
11;0.464;0.244;0.526;0.155;8;Dy_auto
12;0.681;0.295;0.433;0.227;9.66;Dy_auto
13;1;0.353;0.353;0.334;11.6;Dy_auto
14;1.47;0.428;0.291;0.49;14;Dy_auto
15;2.15;0.514;0.238;0.719;16.8;Dy_auto
16;3.16;0.617;0.195;1.06;20.2;Dy_auto
17;4.64;0.739;0.159;1.55;24.2;Dy_auto
18;6.81;0.882;0.129;2.27;28.9;Dy_auto
19;10;1.05;0.105;3.34;34.5;Dy_auto
20;14.7;1.26;0.0857;4.9;41.2;Dy_auto
21;21.5;1.5;0.0696;7.19;49.1;Dy_auto
22;31.6;1.8;0.057;10.6;59.1;Dy_auto
23;46.4;2.16;0.0466;15.5;70.9;Dy_auto
24;68.1;2.61;0.0383;22.7;85.5;Dy_auto
25;100;3.16;0.0316;33.4;104;Dy_auto
26;147;3.85;0.0262;49;126;Dy_auto
27;215;4.71;0.0219;71.9;154;Dy_auto
28;316;5.79;0.0183;106;190;Dy_auto
29;464;7.18;0.0155;155;235;Dy_auto
30;681;8.93;0.0131;227;293;Dy_auto
31;1000;11.2;0.0112;334;367;Dy_auto

Data Series Information
Name:;;;P3-2 7
Number of Intervals:;;;1
Application:;;;RHEOPLUS/32 V3.61 21006227-33024
Device:;;;MCR302 SN81156610; FW3.65; Slot(9,-1)
Measuring Date/Time:;;;2023/09/19; 16:45
Measuring System:;;;CP50-2-SN42594; d=0.206 mm
Accessories:;;;TU1=P-PTD200-SN81263554

Interval:;;;1
Number of Data Points:;;;31

Time Setting:;;;31 Meas. Pts.
;;;Meas. Pt. Duration 60 ... 5 s log
Measuring Profile:
  Shear Rate;;;d(gamma)/dt = 0.01 ... 1000 1/s log; |Slope| = 6 Pt. / dec

Meas. Pts.;Shear Rate;Shear Stress;Viscosity;Speed;Torque;Status
;[1/s];[Pa];[Pa�Es];[1/min];[��Nm];[]
1;0.01;0.00636;0.637;0.00334;0.209;Dy_auto
2;0.0147;0.012;0.818;0.0049;0.393;Dy_auto
3;0.0215;0.0196;0.908;0.00719;0.641;Dy_auto
4;0.0316;0.0313;0.989;0.0106;1.02;Dy_auto
5;0.0464;0.047;1.01;0.0155;1.54;Dy_auto
6;0.0681;0.065;0.955;0.0227;2.13;Dy_auto
7;0.1;0.0827;0.827;0.0334;2.71;Dy_auto
8;0.147;0.102;0.697;0.049;3.35;Dy_auto
9;0.215;0.126;0.584;0.0719;4.12;Dy_auto
10;0.316;0.157;0.495;0.106;5.13;Dy_auto
11;0.464;0.195;0.421;0.155;6.4;Dy_auto
12;0.681;0.243;0.356;0.227;7.95;Dy_auto
13;1;0.3;0.3;0.334;9.83;Dy_auto
14;1.47;0.368;0.251;0.49;12.1;Dy_auto
15;2.15;0.452;0.21;0.719;14.8;Dy_auto
16;3.16;0.551;0.174;1.06;18.1;Dy_auto
17;4.64;0.669;0.144;1.55;21.9;Dy_auto
18;6.81;0.808;0.119;2.27;26.5;Dy_auto
19;10;0.977;0.0977;3.34;32;Dy_auto
20;14.7;1.18;0.0802;4.9;38.6;Dy_auto
21;21.5;1.42;0.0657;7.19;46.4;Dy_auto
22;31.6;1.71;0.0542;10.6;56.2;Dy_auto
23;46.4;2.07;0.0446;15.5;67.9;Dy_auto
24;68.1;2.51;0.0369;22.7;82.3;Dy_auto
25;100;3.06;0.0306;33.4;100;Dy_auto
26;147;3.74;0.0255;49;123;Dy_auto
27;215;4.6;0.0213;71.9;151;Dy_auto
28;316;5.68;0.018;106;186;Dy_auto
29;464;7.06;0.0152;155;231;Dy_auto
30;681;8.82;0.013;227;289;Dy_auto
31;1000;11.1;0.0111;334;364;Dy_auto

Data Series Information
Name:;;;P3-3 1
Number of Intervals:;;;1
Application:;;;RHEOPLUS/32 V3.61 21006227-33024
Device:;;;MCR302 SN81156610; FW3.65; Slot(9,-1)
Measuring Date/Time:;;;2023/09/19; 17:07
Measuring System:;;;CP50-2-SN42594; d=0.206 mm
Accessories:;;;TU1=P-PTD200-SN81263554

Interval:;;;1
Number of Data Points:;;;31

Time Setting:;;;31 Meas. Pts.
;;;Meas. Pt. Duration 60 ... 5 s log
Measuring Profile:
  Shear Rate;;;d(gamma)/dt = 0.01 ... 1000 1/s log; |Slope| = 6 Pt. / dec

Meas. Pts.;Shear Rate;Shear Stress;Viscosity;Speed;Torque;Status
;[1/s];[Pa];[Pa�Es];[1/min];[��Nm];[]
1;0.00999;0.0569;5.7;0.00333;1.87;Dy_auto
2;0.0147;0.106;7.21;0.0049;3.47;Dy_auto
3;0.0215;0.169;7.85;0.00719;5.54;Dy_auto
4;0.0316;0.3;9.48;0.0105;9.82;Dy_auto
5;0.0464;0.502;10.8;0.0155;16.4;Dy_auto
6;0.0681;0.649;9.52;0.0227;21.2;Dy_auto
7;0.1;0.657;6.57;0.0334;21.5;Dy_auto
8;0.147;0.679;4.63;0.049;22.3;Dy_auto
9;0.215;0.733;3.4;0.0719;24;Dy_auto
10;0.316;0.796;2.52;0.106;26.1;Dy_auto
11;0.464;0.877;1.89;0.155;28.7;Dy_auto
12;0.681;0.969;1.42;0.227;31.7;Dy_auto
13;1;1.08;1.08;0.334;35.3;Dy_auto
14;1.47;1.17;0.797;0.49;38.3;Dy_auto
15;2.15;1.28;0.594;0.719;41.9;Dy_auto
16;3.16;1.4;0.443;1.06;45.9;Dy_auto
17;4.64;1.53;0.33;1.55;50.2;Dy_auto
18;6.81;1.69;0.247;2.27;55.2;Dy_auto
19;10;1.87;0.187;3.34;61.2;Dy_auto
20;14.7;2.1;0.143;4.9;68.6;Dy_auto
21;21.5;2.36;0.109;7.19;77.3;Dy_auto
22;31.6;2.69;0.0851;10.6;88.2;Dy_auto
23;46.4;3.08;0.0663;15.5;101;Dy_auto
24;68.1;3.54;0.0519;22.7;116;Dy_auto
25;100;4.08;0.0408;33.4;134;Dy_auto
26;147;4.77;0.0325;49;156;Dy_auto
27;215;5.63;0.0261;71.9;184;Dy_auto
28;316;6.74;0.0213;106;221;Dy_auto
29;464;8.16;0.0176;155;267;Dy_auto
30;681;9.99;0.0147;227;327;Dy_auto
31;1000;12.3;0.0123;334;403;Dy_auto

Data Series Information
Name:;;;P3-3 2
Number of Intervals:;;;1
Application:;;;RHEOPLUS/32 V3.61 21006227-33024
Device:;;;MCR302 SN81156610; FW3.65; Slot(9,-1)
Measuring Date/Time:;;;2023/09/19; 17:20
Measuring System:;;;CP50-2-SN42594; d=0.206 mm
Accessories:;;;TU1=P-PTD200-SN81263554

Interval:;;;1
Number of Data Points:;;;31

Time Setting:;;;31 Meas. Pts.
;;;Meas. Pt. Duration 60 ... 5 s log
Measuring Profile:
  Shear Rate;;;d(gamma)/dt = 0.01 ... 1000 1/s log; |Slope| = 6 Pt. / dec

Meas. Pts.;Shear Rate;Shear Stress;Viscosity;Speed;Torque;Status
;[1/s];[Pa];[Pa�Es];[1/min];[��Nm];[]
1;0.01;0.0125;1.25;0.00334;0.411;Dy_auto
2;0.0147;0.0216;1.47;0.0049;0.709;Dy_auto
3;0.0215;0.0356;1.65;0.00719;1.17;Dy_auto
4;0.0316;0.0639;2.02;0.0106;2.09;Dy_auto
5;0.0464;0.11;2.36;0.0155;3.59;Dy_auto
6;0.0681;0.151;2.21;0.0227;4.93;Dy_auto
7;0.1;0.173;1.73;0.0334;5.66;Dy_auto
8;0.147;0.188;1.28;0.049;6.17;Dy_auto
9;0.215;0.21;0.973;0.0719;6.87;Dy_auto
10;0.316;0.244;0.771;0.106;7.99;Dy_auto
11;0.464;0.295;0.634;0.155;9.65;Dy_auto
12;0.681;0.354;0.52;0.227;11.6;Dy_auto
13;1;0.42;0.42;0.334;13.8;Dy_auto
14;1.47;0.503;0.343;0.49;16.5;Dy_auto
15;2.15;0.6;0.279;0.719;19.7;Dy_auto
16;3.16;0.715;0.226;1.06;23.4;Dy_auto
17;4.64;0.851;0.183;1.55;27.9;Dy_auto
18;6.81;1.01;0.148;2.27;33;Dy_auto
19;10;1.2;0.12;3.34;39.2;Dy_auto
20;14.7;1.42;0.0966;4.9;46.5;Dy_auto
21;21.5;1.69;0.0783;7.19;55.3;Dy_auto
22;31.6;2.01;0.0635;10.6;65.8;Dy_auto
23;46.4;2.4;0.0518;15.5;78.7;Dy_auto
24;68.1;2.89;0.0423;22.7;94.5;Dy_auto
25;100;3.48;0.0348;33.4;114;Dy_auto
26;147;4.23;0.0288;49;139;Dy_auto
27;215;5.17;0.024;71.9;169;Dy_auto
28;316;6.34;0.0201;106;208;Dy_auto
29;464;7.83;0.0169;155;257;Dy_auto
30;681;9.74;0.0143;227;319;Dy_auto
31;1000;12.2;0.0122;334;399;Dy_auto

Data Series Information
Name:;;;P3-3 3
Number of Intervals:;;;1
Application:;;;RHEOPLUS/32 V3.61 21006227-33024
Device:;;;MCR302 SN81156610; FW3.65; Slot(9,-1)
Measuring Date/Time:;;;2023/09/19; 17:33
Measuring System:;;;CP50-2-SN42594; d=0.206 mm
Accessories:;;;TU1=P-PTD200-SN81263554

Interval:;;;1
Number of Data Points:;;;31

Time Setting:;;;31 Meas. Pts.
;;;Meas. Pt. Duration 60 ... 5 s log
Measuring Profile:
  Shear Rate;;;d(gamma)/dt = 0.01 ... 1000 1/s log; |Slope| = 6 Pt. / dec

Meas. Pts.;Shear Rate;Shear Stress;Viscosity;Speed;Torque;Status
;[1/s];[Pa];[Pa�Es];[1/min];[��Nm];[]
1;0.01;0.00685;0.685;0.00334;0.224;Dy_auto
2;0.0147;0.0158;1.07;0.0049;0.517;Dy_auto
3;0.0215;0.027;1.25;0.00719;0.885;Dy_auto
4;0.0316;0.0468;1.48;0.0106;1.53;Dy_auto
5;0.0464;0.0781;1.68;0.0155;2.56;Dy_auto
6;0.0681;0.11;1.61;0.0227;3.6;Dy_auto
7;0.1;0.13;1.3;0.0334;4.27;Dy_auto
8;0.147;0.148;1.01;0.049;4.86;Dy_auto
9;0.215;0.173;0.802;0.0719;5.66;Dy_auto
10;0.316;0.206;0.653;0.106;6.76;Dy_auto
11;0.464;0.253;0.545;0.155;8.28;Dy_auto
12;0.681;0.308;0.452;0.227;10.1;Dy_auto
13;1;0.372;0.372;0.334;12.2;Dy_auto
14;1.47;0.451;0.307;0.49;14.8;Dy_auto
15;2.15;0.546;0.253;0.719;17.9;Dy_auto
16;3.16;0.658;0.208;1.06;21.5;Dy_auto
17;4.64;0.788;0.17;1.55;25.8;Dy_auto
18;6.81;0.944;0.139;2.27;30.9;Dy_auto
19;10;1.13;0.113;3.34;36.9;Dy_auto
20;14.7;1.34;0.0916;4.9;44.1;Dy_auto
21;21.5;1.61;0.0747;7.19;52.8;Dy_auto
22;31.6;1.94;0.0612;10.6;63.5;Dy_auto
23;46.4;2.33;0.0502;15.5;76.3;Dy_auto
24;68.1;2.81;0.0412;22.7;92;Dy_auto
25;100;3.4;0.034;33.4;112;Dy_auto
26;147;4.15;0.0283;49;136;Dy_auto
27;215;5.08;0.0236;71.9;166;Dy_auto
28;316;6.26;0.0198;106;205;Dy_auto
29;464;7.76;0.0167;155;254;Dy_auto
30;681;9.65;0.0142;227;316;Dy_auto
31;1000;12.1;0.0121;334;397;Dy_auto

Data Series Information
Name:;;;P20-1 1
Number of Intervals:;;;1
Application:;;;RHEOPLUS/32 V3.61 21006227-33024
Device:;;;MCR302 SN81156610; FW3.65; Slot(9,-1)
Measuring Date/Time:;;;2023/09/19; 17:49
Measuring System:;;;CP50-2-SN42594; d=0.206 mm
Accessories:;;;TU1=P-PTD200-SN81263554

Interval:;;;1
Number of Data Points:;;;1

Time Setting:;;;31 Meas. Pts.
;;;Meas. Pt. Duration 60 ... 5 s log
Measuring Profile:
  Shear Rate;;;d(gamma)/dt = 0.01 ... 1000 1/s log; |Slope| = 6 Pt. / dec

Meas. Pts.;Shear Rate;Shear Stress;Viscosity;Speed;Torque;Status
;[1/s];[Pa];[Pa�Es];[1/min];[��Nm];[]
1;0.01;-0.000153;-0.0153;0.00334;-0.00502;M- ,Dy_

Data Series Information
Name:;;;P20-1 2
Number of Intervals:;;;1
Application:;;;RHEOPLUS/32 V3.61 21006227-33024
Device:;;;MCR302 SN81156610; FW3.65; Slot(9,-1)
Measuring Date/Time:;;;2023/09/19; 17:53
Measuring System:;;;CP50-2-SN42594; d=0.206 mm
Accessories:;;;TU1=P-PTD200-SN81263554

Interval:;;;1
Number of Data Points:;;;31

Time Setting:;;;31 Meas. Pts.
;;;Meas. Pt. Duration 60 ... 5 s log
Measuring Profile:
  Shear Rate;;;d(gamma)/dt = 0.01 ... 1000 1/s log; |Slope| = 6 Pt. / dec

Meas. Pts.;Shear Rate;Shear Stress;Viscosity;Speed;Torque;Status
;[1/s];[Pa];[Pa�Es];[1/min];[��Nm];[]
1;0.01;0.00176;0.176;0.00334;0.0576;Dy_auto
2;0.0147;0.0032;0.218;0.0049;0.105;Dy_auto
3;0.0215;0.00444;0.206;0.00719;0.145;Dy_auto
4;0.0316;0.00283;0.0896;0.0106;0.0928;Dy_auto
5;0.0464;0.00133;0.0286;0.0155;0.0435;Dy_auto
6;0.0681;0.00164;0.0241;0.0227;0.0538;Dy_auto
7;0.1;0.00229;0.0229;0.0334;0.0751;Dy_auto
8;0.147;0.00405;0.0276;0.049;0.133;Dy_auto
9;0.215;0.00552;0.0256;0.0719;0.181;Dy_auto
10;0.316;0.00838;0.0265;0.106;0.274;Dy_auto
11;0.464;0.012;0.0258;0.155;0.392;Dy_auto
12;0.681;0.0169;0.0248;0.227;0.554;Dy_auto
13;1;0.0249;0.0249;0.334;0.817;Dy_auto
14;1.47;0.0352;0.024;0.49;1.15;Dy_auto
15;2.15;0.0485;0.0225;0.719;1.59;Dy_auto
16;3.16;0.0667;0.0211;1.06;2.19;Dy_auto
17;4.64;0.0926;0.02;1.55;3.03;Dy_auto
18;6.81;0.126;0.0184;2.27;4.12;Dy_auto
19;10;0.171;0.0171;3.34;5.61;Dy_auto
20;14.7;0.231;0.0157;4.9;7.56;Dy_auto
21;21.5;0.309;0.0143;7.19;10.1;Dy_auto
22;31.6;0.412;0.013;10.6;13.5;Dy_auto
23;46.4;0.548;0.0118;15.5;17.9;Dy_auto
24;68.1;0.728;0.0107;22.7;23.8;Dy_auto
25;100;0.962;0.00962;33.4;31.5;Dy_auto
26;147;1.28;0.0087;49;41.8;Dy_auto
27;215;1.69;0.00786;71.9;55.5;Dy_auto
28;316;2.25;0.00711;106;73.7;Dy_auto
29;464;2.99;0.00644;155;98;Dy_auto
30;681;4.03;0.00591;227;132;Dy_auto
31;1000;5.48;0.00548;334;180;Dy_auto

Data Series Information
Name:;;;P20-2 1
Number of Intervals:;;;1
Application:;;;RHEOPLUS/32 V3.61 21006227-33024
Device:;;;MCR302 SN81156610; FW3.65; Slot(9,-1)
Measuring Date/Time:;;;2023/09/19; 18:08
Measuring System:;;;CP50-2-SN42594; d=0.206 mm
Accessories:;;;TU1=P-PTD200-SN81263554

Interval:;;;1
Number of Data Points:;;;1

Time Setting:;;;31 Meas. Pts.
;;;Meas. Pt. Duration 60 ... 5 s log
Measuring Profile:
  Shear Rate;;;d(gamma)/dt = 0.01 ... 1000 1/s log; |Slope| = 6 Pt. / dec

Meas. Pts.;Shear Rate;Shear Stress;Viscosity;Speed;Torque;Status
;[1/s];[Pa];[Pa�Es];[1/min];[��Nm];[]
1;0.01;-0.000107;-0.0107;0.00334;-0.00349;M- ,Dy_

Data Series Information
Name:;;;P20-2 2
Number of Intervals:;;;1
Application:;;;RHEOPLUS/32 V3.61 21006227-33024
Device:;;;MCR302 SN81156610; FW3.65; Slot(9,-1)
Measuring Date/Time:;;;2023/09/19; 18:11
Measuring System:;;;CP50-2-SN42594; d=0.206 mm
Accessories:;;;TU1=P-PTD200-SN81263554

Interval:;;;1
Number of Data Points:;;;1

Time Setting:;;;31 Meas. Pts.
;;;Meas. Pt. Duration 60 ... 5 s log
Measuring Profile:
  Shear Rate;;;d(gamma)/dt = 0.01 ... 1000 1/s log; |Slope| = 6 Pt. / dec

Meas. Pts.;Shear Rate;Shear Stress;Viscosity;Speed;Torque;Status
;[1/s];[Pa];[Pa�Es];[1/min];[��Nm];[]
1;0.01;-0.000255;-0.0255;0.00334;-0.00834;M- ,Dy_

Data Series Information
Name:;;;P20-2 3
Number of Intervals:;;;1
Application:;;;RHEOPLUS/32 V3.61 21006227-33024
Device:;;;MCR302 SN81156610; FW3.65; Slot(9,-1)
Measuring Date/Time:;;;2023/09/19; 18:13
Measuring System:;;;CP50-2-SN42594; d=0.206 mm
Accessories:;;;TU1=P-PTD200-SN81263554

Interval:;;;1
Number of Data Points:;;;31

Time Setting:;;;31 Meas. Pts.
;;;Meas. Pt. Duration 60 ... 5 s log
Measuring Profile:
  Shear Rate;;;d(gamma)/dt = 0.01 ... 1000 1/s log; |Slope| = 6 Pt. / dec

Meas. Pts.;Shear Rate;Shear Stress;Viscosity;Speed;Torque;Status
;[1/s];[Pa];[Pa�Es];[1/min];[��Nm];[]
1;0.01;0.000169;0.0169;0.00334;0.00555;M- ,Dy_
2;0.0147;0.000642;0.0437;0.0049;0.021;Dy_auto
3;0.0215;0.000551;0.0256;0.00719;0.0181;Dy_auto
4;0.0316;0.000657;0.0208;0.0106;0.0215;Dy_auto
5;0.0464;0.00153;0.033;0.0155;0.0503;Dy_auto
6;0.0681;0.00176;0.0258;0.0227;0.0576;Dy_auto
7;0.1;0.00081;0.0081;0.0334;0.0265;Dy_auto
8;0.147;0.00276;0.0188;0.049;0.0904;Dy_auto
9;0.215;0.00498;0.0231;0.0719;0.163;Dy_auto
10;0.316;0.00655;0.0207;0.106;0.215;Dy_auto
11;0.464;0.01;0.0216;0.155;0.329;Dy_auto
12;0.681;0.0154;0.0226;0.227;0.504;Dy_auto
13;1;0.0211;0.0211;0.334;0.692;Dy_auto
14;1.47;0.0302;0.0206;0.49;0.989;Dy_auto
15;2.15;0.0415;0.0192;0.719;1.36;Dy_auto
16;3.16;0.0593;0.0187;1.06;1.94;Dy_auto
17;4.64;0.0828;0.0178;1.55;2.71;Dy_auto
18;6.81;0.113;0.0166;2.27;3.71;Dy_auto
19;10;0.155;0.0155;3.34;5.07;Dy_auto
20;14.7;0.21;0.0143;4.9;6.89;Dy_auto
21;21.5;0.283;0.0132;7.19;9.29;Dy_auto
22;31.6;0.381;0.012;10.6;12.5;Dy_auto
23;46.4;0.509;0.011;15.5;16.7;Dy_auto
24;68.1;0.679;0.00996;22.7;22.2;Dy_auto
25;100;0.903;0.00903;33.4;29.6;Dy_auto
26;147;1.2;0.00818;49;39.3;Dy_auto
27;215;1.59;0.0074;71.9;52.3;Dy_auto
28;316;2.12;0.00671;106;69.5;Dy_auto
29;464;2.84;0.00611;155;93;Dy_auto
30;681;3.82;0.0056;227;125;Dy_auto
31;1000;5.22;0.00523;334;171;Dy_auto

Data Series Information
Name:;;;P20-3 1
Number of Intervals:;;;1
Application:;;;RHEOPLUS/32 V3.61 21006227-33024
Device:;;;MCR302 SN81156610; FW3.65; Slot(9,-1)
Measuring Date/Time:;;;2023/09/19; 18:36
Measuring System:;;;CP50-2-SN42594; d=0.206 mm
Accessories:;;;TU1=P-PTD200-SN81263554

Interval:;;;1
Number of Data Points:;;;31

Time Setting:;;;31 Meas. Pts.
;;;Meas. Pt. Duration 60 ... 5 s log
Measuring Profile:
  Shear Rate;;;d(gamma)/dt = 0.01 ... 1000 1/s log; |Slope| = 6 Pt. / dec

Meas. Pts.;Shear Rate;Shear Stress;Viscosity;Speed;Torque;Status
;[1/s];[Pa];[Pa�Es];[1/min];[��Nm];[]
1;0.01;-0.000237;-0.0237;0.00334;-0.00778;M- ,Dy_
2;0.0147;0.000176;0.012;0.0049;0.00576;M- ,Dy_
3;0.0215;0.00135;0.0626;0.00719;0.0442;Dy_auto
4;0.0316;0.00187;0.0591;0.0106;0.0612;Dy_auto
5;0.0464;0.00214;0.0462;0.0155;0.0702;Dy_auto
6;0.0681;0.00226;0.0331;0.0227;0.0739;Dy_auto
7;0.1;0.00237;0.0237;0.0334;0.0776;Dy_auto
8;0.147;0.00437;0.0298;0.049;0.143;Dy_auto
9;0.215;0.00554;0.0257;0.0719;0.182;Dy_auto
10;0.316;0.0077;0.0243;0.106;0.252;Dy_auto
11;0.464;0.0111;0.0239;0.155;0.363;Dy_auto
12;0.681;0.0159;0.0233;0.227;0.52;Dy_auto
13;1;0.0235;0.0235;0.334;0.77;Dy_auto
14;1.47;0.0332;0.0226;0.49;1.09;Dy_auto
15;2.15;0.0462;0.0214;0.719;1.51;Dy_auto
16;3.16;0.0638;0.0202;1.06;2.09;Dy_auto
17;4.64;0.089;0.0192;1.55;2.92;Dy_auto
18;6.81;0.121;0.0178;2.27;3.98;Dy_auto
19;10;0.166;0.0166;3.34;5.45;Dy_auto
20;14.7;0.225;0.0153;4.9;7.37;Dy_auto
21;21.5;0.302;0.014;7.19;9.89;Dy_auto
22;31.6;0.404;0.0128;10.6;13.3;Dy_auto
23;46.4;0.539;0.0116;15.5;17.7;Dy_auto
24;68.1;0.718;0.0105;22.7;23.5;Dy_auto
25;100;0.952;0.00952;33.4;31.2;Dy_auto
26;147;1.27;0.00862;49;41.5;Dy_auto
27;215;1.68;0.0078;71.9;55.1;Dy_auto
28;316;2.24;0.00707;106;73.3;Dy_auto
29;464;2.98;0.00642;155;97.6;Dy_auto
30;681;4.02;0.0059;227;132;Dy_auto
31;1000;5.49;0.00549;334;180;Dy_auto

Data Series Information
Name:;;;P20-4 1
Number of Intervals:;;;1
Application:;;;RHEOPLUS/32 V3.61 21006227-33024
Device:;;;MCR302 SN81156610; FW3.65; Slot(9,-1)
Measuring Date/Time:;;;2023/09/19; 18:52
Measuring System:;;;CP50-2-SN42594; d=0.206 mm
Accessories:;;;TU1=P-PTD200-SN81263554

Interval:;;;1
Number of Data Points:;;;31

Time Setting:;;;31 Meas. Pts.
;;;Meas. Pt. Duration 60 ... 5 s log
Measuring Profile:
  Shear Rate;;;d(gamma)/dt = 0.01 ... 1000 1/s log; |Slope| = 6 Pt. / dec

Meas. Pts.;Shear Rate;Shear Stress;Viscosity;Speed;Torque;Status
;[1/s];[Pa];[Pa�Es];[1/min];[��Nm];[]
1;0.01;-0.00024;-0.024;0.00334;-0.00787;M- ,Dy_
2;0.0147;0.000241;0.0164;0.0049;0.00788;M- ,Dy_
3;0.0215;0.00132;0.0614;0.00719;0.0434;Dy_auto
4;0.0316;0.00174;0.0549;0.0106;0.0569;Dy_auto
5;0.0464;0.00188;0.0405;0.0155;0.0615;Dy_auto
6;0.0681;0.00197;0.0289;0.0227;0.0645;Dy_auto
7;0.1;0.00247;0.0247;0.0334;0.081;Dy_auto
8;0.147;0.00466;0.0317;0.049;0.153;Dy_auto
9;0.215;0.00569;0.0264;0.0719;0.186;Dy_auto
10;0.316;0.00813;0.0257;0.106;0.266;Dy_auto
11;0.464;0.0115;0.0248;0.155;0.377;Dy_auto
12;0.681;0.0165;0.0242;0.227;0.541;Dy_auto
13;1;0.0243;0.0243;0.334;0.796;Dy_auto
14;1.47;0.0342;0.0233;0.49;1.12;Dy_auto
15;2.15;0.0476;0.0221;0.719;1.56;Dy_auto
16;3.16;0.0655;0.0207;1.06;2.15;Dy_auto
17;4.64;0.0911;0.0196;1.55;2.99;Dy_auto
18;6.81;0.124;0.0182;2.27;4.07;Dy_auto
19;10;0.17;0.017;3.34;5.56;Dy_auto
20;14.7;0.229;0.0156;4.9;7.51;Dy_auto
21;21.5;0.307;0.0143;7.19;10.1;Dy_auto
22;31.6;0.411;0.013;10.6;13.5;Dy_auto
23;46.4;0.548;0.0118;15.5;18;Dy_auto
24;68.1;0.729;0.0107;22.7;23.9;Dy_auto
25;100;0.966;0.00966;33.4;31.7;Dy_auto
26;147;1.28;0.00874;49;42;Dy_auto
27;215;1.7;0.00791;71.9;55.8;Dy_auto
28;316;2.27;0.00717;106;74.3;Dy_auto
29;464;3.02;0.0065;155;98.9;Dy_auto
30;681;4.07;0.00597;227;133;Dy_auto
31;1000;5.55;0.00555;334;182;Dy_auto

Data Series Information
Name:;;;P40-1 1
Number of Intervals:;;;1
Application:;;;RHEOPLUS/32 V3.61 21006227-33024
Device:;;;MCR302 SN81156610; FW3.65; Slot(9,-1)
Measuring Date/Time:;;;2023/09/19; 19:07
Measuring System:;;;CP50-2-SN42594; d=0.206 mm
Accessories:;;;TU1=P-PTD200-SN81263554

Interval:;;;1
Number of Data Points:;;;31

Time Setting:;;;31 Meas. Pts.
;;;Meas. Pt. Duration 60 ... 5 s log
Measuring Profile:
  Shear Rate;;;d(gamma)/dt = 0.01 ... 1000 1/s log; |Slope| = 6 Pt. / dec

Meas. Pts.;Shear Rate;Shear Stress;Viscosity;Speed;Torque;Status
;[1/s];[Pa];[Pa�Es];[1/min];[��Nm];[]
1;0.01;0.0000749;0.00749;0.00334;0.00246;M- ,Dy_
2;0.0147;0.000355;0.0242;0.0049;0.0116;Dy_auto
3;0.0215;0.00147;0.0682;0.00719;0.0481;Dy_auto
4;0.0316;0.00138;0.0438;0.0106;0.0453;Dy_auto
5;0.0464;0.00113;0.0242;0.0155;0.0369;Dy_auto
6;0.0681;0.000503;0.00739;0.0227;0.0165;Dy_auto
7;0.1;0.000553;0.00553;0.0334;0.0181;Dy_auto
8;0.147;0.0018;0.0123;0.049;0.059;Dy_auto
9;0.215;0.00179;0.00831;0.0719;0.0586;Dy_auto
10;0.316;0.0025;0.00789;0.106;0.0818;Dy_auto
11;0.464;0.00471;0.0101;0.155;0.154;Dy_auto
12;0.681;0.00664;0.00974;0.227;0.217;Dy_auto
13;1;0.0113;0.0113;0.334;0.369;Dy_auto
14;1.47;0.0163;0.0111;0.49;0.535;Dy_auto
15;2.15;0.0234;0.0109;0.719;0.767;Dy_auto
16;3.16;0.0328;0.0104;1.06;1.07;Dy_auto
17;4.64;0.048;0.0103;1.55;1.57;Dy_auto
18;6.81;0.0678;0.00996;2.27;2.22;Dy_auto
19;10;0.0969;0.00969;3.34;3.18;Dy_auto
20;14.7;0.136;0.00927;4.9;4.46;Dy_auto
21;21.5;0.189;0.00878;7.19;6.2;Dy_auto
22;31.6;0.262;0.0083;10.6;8.6;Dy_auto
23;46.4;0.362;0.00779;15.5;11.9;Dy_auto
24;68.1;0.497;0.0073;22.7;16.3;Dy_auto
25;100;0.678;0.00678;33.4;22.2;Dy_auto
26;147;0.926;0.00631;49;30.3;Dy_auto
27;215;1.26;0.00585;71.9;41.3;Dy_auto
28;316;1.71;0.00542;106;56.2;Dy_auto
29;464;2.33;0.00502;155;76.4;Dy_auto
30;681;3.22;0.00472;227;105;Dy_auto
31;1000;4.53;0.00453;334;148;Dy_auto

Data Series Information
Name:;;;P40-2 1
Number of Intervals:;;;1
Application:;;;RHEOPLUS/32 V3.61 21006227-33024
Device:;;;MCR302 SN81156610; FW3.65; Slot(9,-1)
Measuring Date/Time:;;;2023/09/19; 19:24
Measuring System:;;;CP50-2-SN42594; d=0.206 mm
Accessories:;;;TU1=P-PTD200-SN81263554

Interval:;;;1
Number of Data Points:;;;2

Time Setting:;;;31 Meas. Pts.
;;;Meas. Pt. Duration 60 ... 5 s log
Measuring Profile:
  Shear Rate;;;d(gamma)/dt = 0.01 ... 1000 1/s log; |Slope| = 6 Pt. / dec

Meas. Pts.;Shear Rate;Shear Stress;Viscosity;Speed;Torque;Status
;[1/s];[Pa];[Pa�Es];[1/min];[��Nm];[]
1;0.01;-0.000538;-0.0538;0.00334;-0.0176;Dy_auto
2;0.0147;-0.000101;-0.00688;0.0049;-0.00331;M- ,Dy_

Data Series Information
Name:;;;P40-2 2
Number of Intervals:;;;1
Application:;;;RHEOPLUS/32 V3.61 21006227-33024
Device:;;;MCR302 SN81156610; FW3.65; Slot(9,-1)
Measuring Date/Time:;;;2023/09/19; 19:28
Measuring System:;;;CP50-2-SN42594; d=0.206 mm
Accessories:;;;TU1=P-PTD200-SN81263554

Interval:;;;1
Number of Data Points:;;;31

Time Setting:;;;31 Meas. Pts.
;;;Meas. Pt. Duration 60 ... 5 s log
Measuring Profile:
  Shear Rate;;;d(gamma)/dt = 0.01 ... 1000 1/s log; |Slope| = 6 Pt. / dec

Meas. Pts.;Shear Rate;Shear Stress;Viscosity;Speed;Torque;Status
;[1/s];[Pa];[Pa�Es];[1/min];[��Nm];[]
1;0.01;-0.000359;-0.0359;0.00334;-0.0118;Dy_auto
2;0.0147;-0.000244;-0.0166;0.0049;-0.00799;M- ,Dy_
3;0.0215;0.00071;0.033;0.00719;0.0233;Dy_auto
4;0.0316;0.00075;0.0237;0.0106;0.0246;Dy_auto
5;0.0464;0.0005;0.0108;0.0155;0.0164;Dy_auto
6;0.0681;0.000531;0.0078;0.0227;0.0174;Dy_auto
7;0.1;0.000875;0.00875;0.0334;0.0287;Dy_auto
8;0.147;0.00196;0.0134;0.049;0.0644;Dy_auto
9;0.215;0.00236;0.011;0.0719;0.0773;Dy_auto
10;0.316;0.00327;0.0103;0.106;0.107;Dy_auto
11;0.464;0.0046;0.0099;0.155;0.151;Dy_auto
12;0.681;0.00704;0.0103;0.227;0.231;Dy_auto
13;1;0.0111;0.0111;0.334;0.365;Dy_auto
14;1.47;0.0165;0.0112;0.49;0.541;Dy_auto
15;2.15;0.0236;0.011;0.719;0.773;Dy_auto
16;3.16;0.0325;0.0103;1.06;1.07;Dy_auto
17;4.64;0.0482;0.0104;1.55;1.58;Dy_auto
18;6.81;0.068;0.00997;2.27;2.23;Dy_auto
19;10;0.0975;0.00975;3.34;3.19;Dy_auto
[...]
Measuring System:;;;CP50-2-SN42594; d=0.206 mm
Accessories:;;;TU1=P-PTD200-SN81263554

Interval:;;;1
Number of Data Points:;;;31

Time Setting:;;;31 Meas. Pts.
;;;Meas. Pt. Duration 60 ... 5 s log
Measuring Profile:
  Shear Rate;;;d(gamma)/dt = 0.01 ... 1000 1/s log; |Slope| = 6 Pt. / dec

Meas. Pts.;Shear Rate;Shear Stress;Viscosity;Speed;Torque;Status
;[1/s];[Pa];[Pa�Es];[1/min];[��Nm];[]
1;0.01;0.00328;0.328;0.00334;0.108;Dy_auto
2;0.0147;0.00573;0.391;0.0049;0.188;Dy_auto
3;0.0215;0.00959;0.445;0.00719;0.314;Dy_auto
4;0.0316;0.014;0.443;0.0106;0.459;Dy_auto
5;0.0464;0.0193;0.415;0.0155;0.632;Dy_auto
6;0.0681;0.0262;0.384;0.0227;0.857;Dy_auto
7;0.1;0.0345;0.345;0.0334;1.13;Dy_auto
8;0.147;0.0452;0.308;0.049;1.48;Dy_auto
9;0.215;0.0567;0.263;0.0719;1.86;Dy_auto
10;0.316;0.0716;0.227;0.106;2.35;Dy_auto
11;0.464;0.0908;0.196;0.155;2.98;Dy_auto
12;0.681;0.116;0.17;0.227;3.79;Dy_auto
13;1;0.148;0.148;0.334;4.85;Dy_auto
14;1.47;0.188;0.128;0.49;6.17;Dy_auto
15;2.15;0.238;0.11;0.719;7.8;Dy_auto
16;3.16;0.297;0.094;1.06;9.74;Dy_auto
17;4.64;0.375;0.0807;1.55;12.3;Dy_auto
18;6.81;0.47;0.0689;2.27;15.4;Dy_auto
19;10;0.59;0.059;3.34;19.3;Dy_auto
20;14.7;0.734;0.05;4.9;24;Dy_auto
21;21.5;0.913;0.0424;7.19;29.9;Dy_auto
22;31.6;1.14;0.0359;10.6;37.2;Dy_auto
23;46.4;1.41;0.0304;15.5;46.2;Dy_auto
24;68.1;1.76;0.0258;22.7;57.6;Dy_auto
25;100;2.2;0.022;33.4;71.9;Dy_auto
26;147;2.74;0.0187;49;89.8;Dy_auto
27;215;3.43;0.0159;71.9;112;Dy_auto
28;316;4.32;0.0137;106;142;Dy_auto
29;464;5.46;0.0118;155;179;Dy_auto
30;681;6.95;0.0102;227;228;Dy_auto
31;1000;8.89;0.00889;334;291;Dy_auto

Data Series Information
Name:;;;1-2 1
Number of Intervals:;;;1
Application:;;;RHEOPLUS/32 V3.61 21006227-33024
Device:;;;MCR302 SN81156610; FW3.65; Slot(9,-1)
Measuring Date/Time:;;;2023/09/19; 20:23
Measuring System:;;;CP50-2-SN42594; d=0.206 mm
Accessories:;;;TU1=P-PTD200-SN81263554

Interval:;;;1
Number of Data Points:;;;31

Time Setting:;;;31 Meas. Pts.
;;;Meas. Pt. Duration 60 ... 5 s log
Measuring Profile:
  Shear Rate;;;d(gamma)/dt = 0.01 ... 1000 1/s log; |Slope| = 6 Pt. / dec

Meas. Pts.;Shear Rate;Shear Stress;Viscosity;Speed;Torque;Status
;[1/s];[Pa];[Pa�Es];[1/min];[��Nm];[]
1;0.01;0.00303;0.303;0.00334;0.0993;Dy_auto
2;0.0147;0.0058;0.395;0.0049;0.19;Dy_auto
3;0.0215;0.00972;0.451;0.00719;0.318;Dy_auto
4;0.0316;0.0138;0.438;0.0106;0.454;Dy_auto
5;0.0464;0.0187;0.404;0.0155;0.614;Dy_auto
6;0.0681;0.025;0.367;0.0227;0.82;Dy_auto
7;0.1;0.0327;0.327;0.0334;1.07;Dy_auto
8;0.147;0.0427;0.291;0.049;1.4;Dy_auto
9;0.215;0.0534;0.248;0.0719;1.75;Dy_auto
10;0.316;0.0679;0.215;0.106;2.23;Dy_auto
11;0.464;0.0874;0.188;0.155;2.86;Dy_auto
12;0.681;0.111;0.163;0.227;3.63;Dy_auto
13;1;0.142;0.142;0.334;4.66;Dy_auto
14;1.47;0.181;0.124;0.49;5.94;Dy_auto
15;2.15;0.23;0.107;0.719;7.53;Dy_auto
16;3.16;0.289;0.0914;1.06;9.47;Dy_auto
17;4.64;0.366;0.0788;1.55;12;Dy_auto
18;6.81;0.46;0.0675;2.27;15.1;Dy_auto
19;10;0.579;0.0579;3.34;19;Dy_auto
20;14.7;0.725;0.0494;4.9;23.8;Dy_auto
21;21.5;0.904;0.042;7.19;29.6;Dy_auto
22;31.6;1.13;0.0357;10.6;37;Dy_auto
23;46.4;1.41;0.0303;15.5;46.1;Dy_auto
24;68.1;1.76;0.0258;22.7;57.7;Dy_auto
25;100;2.2;0.022;33.4;72.1;Dy_auto
26;147;2.76;0.0188;49;90.3;Dy_auto
27;215;3.46;0.016;71.9;113;Dy_auto
28;316;4.35;0.0138;106;142;Dy_auto
29;464;5.49;0.0118;155;180;Dy_auto
30;681;7;0.0103;227;229;Dy_auto
31;1000;8.94;0.00894;334;293;Dy_auto

Data Series Information
Name:;;;1-3 1
Number of Intervals:;;;1
Application:;;;RHEOPLUS/32 V3.61 21006227-33024
Device:;;;MCR302 SN81156610; FW3.65; Slot(9,-1)
Measuring Date/Time:;;;2023/09/19; 20:39
Measuring System:;;;CP50-2-SN42594; d=0.206 mm
Accessories:;;;TU1=P-PTD200-SN81263554

Interval:;;;1
Number of Data Points:;;;31

Time Setting:;;;31 Meas. Pts.
;;;Meas. Pt. Duration 60 ... 5 s log
Measuring Profile:
  Shear Rate;;;d(gamma)/dt = 0.01 ... 1000 1/s log; |Slope| = 6 Pt. / dec

Meas. Pts.;Shear Rate;Shear Stress;Viscosity;Speed;Torque;Status
;[1/s];[Pa];[Pa�Es];[1/min];[��Nm];[]
1;0.01;0.00352;0.352;0.00334;0.115;Dy_auto
2;0.0147;0.00585;0.399;0.0049;0.192;Dy_auto
3;0.0215;0.00939;0.436;0.00719;0.308;Dy_auto
4;0.0316;0.0129;0.407;0.0106;0.422;Dy_auto
5;0.0464;0.0169;0.364;0.0155;0.553;Dy_auto
6;0.0681;0.0232;0.34;0.0227;0.76;Dy_auto
7;0.1;0.0303;0.303;0.0334;0.994;Dy_auto
8;0.147;0.0397;0.271;0.049;1.3;Dy_auto
9;0.215;0.0502;0.233;0.0719;1.64;Dy_auto
10;0.316;0.0645;0.204;0.106;2.11;Dy_auto
11;0.464;0.0828;0.178;0.155;2.71;Dy_auto
12;0.681;0.107;0.157;0.227;3.5;Dy_auto
13;1;0.138;0.138;0.334;4.52;Dy_auto
14;1.47;0.177;0.12;0.49;5.79;Dy_auto
15;2.15;0.224;0.104;0.719;7.34;Dy_auto
16;3.16;0.283;0.0894;1.06;9.27;Dy_auto
17;4.64;0.358;0.0772;1.55;11.7;Dy_auto
18;6.81;0.452;0.0663;2.27;14.8;Dy_auto
19;10;0.567;0.0567;3.34;18.6;Dy_auto
20;14.7;0.711;0.0484;4.9;23.3;Dy_auto
21;21.5;0.888;0.0412;7.19;29.1;Dy_auto
22;31.6;1.11;0.035;10.6;36.3;Dy_auto
23;46.4;1.38;0.0298;15.5;45.3;Dy_auto
24;68.1;1.73;0.0254;22.7;56.8;Dy_auto
25;100;2.17;0.0217;33.4;70.9;Dy_auto
26;147;2.72;0.0185;49;89;Dy_auto
27;215;3.42;0.0159;71.9;112;Dy_auto
28;316;4.32;0.0137;106;141;Dy_auto
29;464;5.46;0.0118;155;179;Dy_auto
30;681;6.97;0.0102;227;228;Dy_auto
31;1000;8.91;0.00891;334;292;Dy_auto

Data Series Information
Name:;;;2-1 1
Number of Intervals:;;;1
Application:;;;RHEOPLUS/32 V3.61 21006227-33024
Device:;;;MCR302 SN81156610; FW3.65; Slot(9,-1)
Measuring Date/Time:;;;2023/09/19; 20:56
Measuring System:;;;CP50-2-SN42594; d=0.206 mm
Accessories:;;;TU1=P-PTD200-SN81263554

Interval:;;;1
Number of Data Points:;;;31

Time Setting:;;;31 Meas. Pts.
;;;Meas. Pt. Duration 60 ... 5 s log
Measuring Profile:
  Shear Rate;;;d(gamma)/dt = 0.01 ... 1000 1/s log; |Slope| = 6 Pt. / dec

Meas. Pts.;Shear Rate;Shear Stress;Viscosity;Speed;Torque;Status
;[1/s];[Pa];[Pa�Es];[1/min];[��Nm];[]
1;0.01;0.00168;0.168;0.00334;0.0549;Dy_auto
2;0.0147;0.00402;0.274;0.0049;0.132;Dy_auto
3;0.0215;0.00756;0.351;0.00719;0.248;Dy_auto
4;0.0316;0.0103;0.327;0.0106;0.339;Dy_auto
5;0.0464;0.0119;0.255;0.0155;0.388;Dy_auto
6;0.0681;0.0135;0.198;0.0227;0.442;Dy_auto
7;0.1;0.0165;0.165;0.0334;0.539;Dy_auto
8;0.147;0.021;0.143;0.049;0.688;Dy_auto
9;0.215;0.0272;0.126;0.0719;0.891;Dy_auto
10;0.316;0.0344;0.109;0.106;1.13;Dy_auto
11;0.464;0.0455;0.098;0.155;1.49;Dy_auto
12;0.681;0.0596;0.0875;0.227;1.95;Dy_auto
13;1;0.0785;0.0785;0.334;2.57;Dy_auto
14;1.47;0.104;0.0706;0.49;3.39;Dy_auto
15;2.15;0.135;0.0628;0.719;4.43;Dy_auto
16;3.16;0.175;0.0553;1.06;5.73;Dy_auto
17;4.64;0.227;0.0489;1.55;7.43;Dy_auto
18;6.81;0.293;0.043;2.27;9.6;Dy_auto
19;10;0.378;0.0378;3.34;12.4;Dy_auto
20;14.7;0.486;0.0331;4.9;15.9;Dy_auto
21;21.5;0.623;0.0289;7.19;20.4;Dy_auto
22;31.6;0.798;0.0252;10.6;26.1;Dy_auto
23;46.4;1.02;0.022;15.5;33.5;Dy_auto
24;68.1;1.31;0.0192;22.7;42.9;Dy_auto
25;100;1.68;0.0168;33.4;55;Dy_auto
26;147;2.15;0.0147;49;70.6;Dy_auto
27;215;2.77;0.0129;71.9;90.9;Dy_auto
28;316;3.58;0.0113;106;117;Dy_auto
29;464;4.62;0.00996;155;152;Dy_auto
30;681;6.02;0.00884;227;197;Dy_auto
31;1000;7.87;0.00787;334;258;Dy_auto

Data Series Information
Name:;;;2-2 1
Number of Intervals:;;;1
Application:;;;RHEOPLUS/32 V3.61 21006227-33024
Device:;;;MCR302 SN81156610; FW3.65; Slot(9,-1)
Measuring Date/Time:;;;2023/09/19; 21:12
Measuring System:;;;CP50-2-SN42594; d=0.206 mm
Accessories:;;;TU1=P-PTD200-SN81263554

Interval:;;;1
Number of Data Points:;;;0

Time Setting:;;;31 Meas. Pts.
;;;Meas. Pt. Duration 60 ... 5 s log
Measuring Profile:
  Shear Rate;;;d(gamma)/dt = 0.01 ... 1000 1/s log; |Slope| = 6 Pt. / dec

Data Series Information
Name:;;;2-2 2
Number of Intervals:;;;1
Application:;;;RHEOPLUS/32 V3.61 21006227-33024
Device:;;;MCR302 SN81156610; FW3.65; Slot(9,-1)
Measuring Date/Time:;;;2023/09/19; 21:13
Measuring System:;;;CP50-2-SN42594; d=0.206 mm
Accessories:;;;TU1=P-PTD200-SN81263554

Interval:;;;1
Number of Data Points:;;;31

Time Setting:;;;31 Meas. Pts.
;;;Meas. Pt. Duration 60 ... 5 s log
Measuring Profile:
  Shear Rate;;;d(gamma)/dt = 0.01 ... 1000 1/s log; |Slope| = 6 Pt. / dec

Meas. Pts.;Shear Rate;Shear Stress;Viscosity;Speed;Torque;Status
;[1/s];[Pa];[Pa�Es];[1/min];[��Nm];[]
1;0.01;0.0676;6.76;0.00334;2.21;Dy_auto
2;0.0147;0.0713;4.86;0.0049;2.34;Dy_auto
3;0.0215;0.0725;3.36;0.00719;2.38;Dy_auto
4;0.0316;0.0765;2.42;0.0106;2.51;Dy_auto
5;0.0464;0.0712;1.53;0.0155;2.33;Dy_auto
6;0.0681;0.082;1.2;0.0227;2.69;Dy_auto
7;0.1;0.0964;0.964;0.0334;3.16;Dy_auto
8;0.147;0.102;0.696;0.049;3.35;Dy_auto
9;0.215;0.0989;0.459;0.0719;3.24;Dy_auto
10;0.316;0.104;0.33;0.106;3.42;Dy_auto
11;0.464;0.115;0.248;0.155;3.76;Dy_auto
12;0.681;0.128;0.188;0.227;4.2;Dy_auto
13;1;0.144;0.144;0.334;4.7;Dy_auto
14;1.47;0.159;0.109;0.49;5.22;Dy_auto
15;2.15;0.176;0.0818;0.719;5.77;Dy_auto
16;3.16;0.22;0.0697;1.06;7.22;Dy_auto
17;4.64;0.255;0.0549;1.55;8.35;Dy_auto
18;6.81;0.32;0.047;2.27;10.5;Dy_auto
19;10;0.396;0.0396;3.34;13;Dy_auto
20;14.7;0.51;0.0347;4.9;16.7;Dy_auto
21;21.5;0.646;0.03;7.19;21.2;Dy_auto
22;31.6;0.814;0.0257;10.6;26.7;Dy_auto
23;46.4;1.04;0.0223;15.5;33.9;Dy_auto
24;68.1;1.32;0.0193;22.7;43.2;Dy_auto
25;100;1.68;0.0168;33.4;55.1;Dy_auto
26;147;2.14;0.0146;49;70.3;Dy_auto
27;215;2.73;0.0127;71.9;89.5;Dy_auto
28;316;3.5;0.0111;106;115;Dy_auto
29;464;4.47;0.00964;155;147;Dy_auto
30;681;5.77;0.00847;227;189;Dy_auto
31;1000;7.5;0.0075;334;246;Dy_auto

Data Series Information
Name:;;;2-3 1
Number of Intervals:;;;1
Application:;;;RHEOPLUS/32 V3.61 21006227-33024
Device:;;;MCR302 SN81156610; FW3.65; Slot(9,-1)
Measuring Date/Time:;;;2023/09/19; 21:28
Measuring System:;;;CP50-2-SN42594; d=0.206 mm
Accessories:;;;TU1=P-PTD200-SN81263554

Interval:;;;1
Number of Data Points:;;;31

Time Setting:;;;31 Meas. Pts.
;;;Meas. Pt. Duration 60 ... 5 s log
Measuring Profile:
  Shear Rate;;;d(gamma)/dt = 0.01 ... 1000 1/s log; |Slope| = 6 Pt. / dec

Meas. Pts.;Shear Rate;Shear Stress;Viscosity;Speed;Torque;Status
;[1/s];[Pa];[Pa�Es];[1/min];[��Nm];[]
1;0.01;0.000556;0.0556;0.00334;0.0182;Dy_auto
2;0.0147;0.00109;0.0739;0.0049;0.0356;Dy_auto
3;0.0215;0.00278;0.129;0.00719;0.0911;Dy_auto
4;0.0316;0.00426;0.135;0.0106;0.139;Dy_auto
5;0.0464;0.00597;0.129;0.0155;0.196;Dy_auto
6;0.0681;0.00864;0.127;0.0227;0.283;Dy_auto
7;0.1;0.0119;0.119;0.0334;0.389;Dy_auto
8;0.147;0.0167;0.113;0.049;0.546;Dy_auto
9;0.215;0.0221;0.103;0.0719;0.724;Dy_auto
10;0.316;0.0294;0.093;0.106;0.964;Dy_auto
11;0.464;0.0395;0.0851;0.155;1.29;Dy_auto
12;0.681;0.053;0.0778;0.227;1.74;Dy_auto
13;1;0.071;0.071;0.334;2.33;Dy_auto
14;1.47;0.0949;0.0646;0.49;3.11;Dy_auto
15;2.15;0.124;0.0576;0.719;4.07;Dy_auto
16;3.16;0.161;0.0509;1.06;5.28;Dy_auto
17;4.64;0.211;0.0454;1.55;6.9;Dy_auto
18;6.81;0.273;0.0401;2.27;8.94;Dy_auto
19;10;0.354;0.0354;3.34;11.6;Dy_auto
20;14.7;0.457;0.0311;4.9;15;Dy_auto
21;21.5;0.587;0.0273;7.19;19.2;Dy_auto
22;31.6;0.755;0.0239;10.6;24.7;Dy_auto
23;46.4;0.97;0.0209;15.5;31.8;Dy_auto
24;68.1;1.25;0.0183;22.7;40.9;Dy_auto
25;100;1.61;0.0161;33.4;52.6;Dy_auto
26;147;2.07;0.0141;49;67.9;Dy_auto
27;215;2.68;0.0124;71.9;87.8;Dy_auto
28;316;3.47;0.011;106;114;Dy_auto
29;464;4.5;0.0097;155;147;Dy_auto
30;681;5.89;0.00865;227;193;Dy_auto
31;1000;7.74;0.00774;334;253;Dy_auto

Data Series Information
Name:;;;2-4 1
Number of Intervals:;;;1
Application:;;;RHEOPLUS/32 V3.61 21006227-33024
Device:;;;MCR302 SN81156610; FW3.65; Slot(9,-1)
Measuring Date/Time:;;;2023/09/19; 21:44
Measuring System:;;;CP50-2-SN42594; d=0.206 mm
Accessories:;;;TU1=P-PTD200-SN81263554

Interval:;;;1
Number of Data Points:;;;31

Time Setting:;;;31 Meas. Pts.
;;;Meas. Pt. Duration 60 ... 5 s log
Measuring Profile:
  Shear Rate;;;d(gamma)/dt = 0.01 ... 1000 1/s log; |Slope| = 6 Pt. / dec

Meas. Pts.;Shear Rate;Shear Stress;Viscosity;Speed;Torque;Status
;[1/s];[Pa];[Pa�Es];[1/min];[��Nm];[]
1;0.01;0.00121;0.121;0.00334;0.0396;Dy_auto
2;0.0147;0.00205;0.14;0.0049;0.0671;Dy_auto
3;0.0215;0.00403;0.187;0.00719;0.132;Dy_auto
4;0.0316;0.00598;0.189;0.0106;0.196;Dy_auto
5;0.0464;0.00746;0.161;0.0155;0.244;Dy_auto
6;0.0681;0.00971;0.143;0.0227;0.318;Dy_auto
7;0.1;0.0126;0.126;0.0334;0.413;Dy_auto
8;0.147;0.0181;0.123;0.049;0.592;Dy_auto
9;0.215;0.0235;0.109;0.0719;0.769;Dy_auto
10;0.316;0.0314;0.0992;0.106;1.03;Dy_auto
11;0.464;0.0417;0.0899;0.155;1.37;Dy_auto
12;0.681;0.0553;0.0811;0.227;1.81;Dy_auto
13;1;0.0742;0.0742;0.334;2.43;Dy_auto
14;1.47;0.0981;0.0668;0.49;3.21;Dy_auto
15;2.15;0.128;0.0593;0.719;4.19;Dy_auto
16;3.16;0.165;0.0522;1.06;5.41;Dy_auto
17;4.64;0.215;0.0464;1.55;7.05;Dy_auto
18;6.81;0.278;0.0408;2.27;9.1;Dy_auto
19;10;0.36;0.036;3.34;11.8;Dy_auto
20;14.7;0.463;0.0315;4.9;15.2;Dy_auto
21;21.5;0.595;0.0276;7.19;19.5;Dy_auto
22;31.6;0.764;0.0242;10.6;25;Dy_auto
23;46.4;0.981;0.0211;15.5;32.1;Dy_auto
24;68.1;1.26;0.0185;22.7;41.3;Dy_auto
25;100;1.62;0.0162;33.4;53.1;Dy_auto
26;147;2.09;0.0142;49;68.4;Dy_auto
27;215;2.69;0.0125;71.9;88.3;Dy_auto
28;316;3.49;0.011;106;114;Dy_auto
29;464;4.52;0.00973;155;148;Dy_auto
30;681;5.89;0.00864;227;193;Dy_auto
31;1000;7.71;0.00771;334;252;Dy_auto

Data Series Information
Name:;;;3-1 1
Number of Intervals:;;;1
Application:;;;RHEOPLUS/32 V3.61 21006227-33024
Device:;;;MCR302 SN81156610; FW3.65; Slot(9,-1)
Measuring Date/Time:;;;2023/09/19; 22:01
Measuring System:;;;CP50-2-SN42594; d=0.206 mm
Accessories:;;;TU1=P-PTD200-SN81263554

Interval:;;;1
Number of Data Points:;;;31

Time Setting:;;;31 Meas. Pts.
;;;Meas. Pt. Duration 60 ... 5 s log
Measuring Profile:
  Shear Rate;;;d(gamma)/dt = 0.01 ... 1000 1/s log; |Slope| = 6 Pt. / dec

Meas. Pts.;Shear Rate;Shear Stress;Viscosity;Speed;Torque;Status
;[1/s];[Pa];[Pa�Es];[1/min];[��Nm];[]
1;0.01;-0.000565;-0.0565;0.00334;-0.0185;Dy_auto
2;0.0147;0.00355;0.242;0.0049;0.116;Dy_auto
3;0.0215;0.00985;0.457;0.00719;0.323;Dy_auto
4;0.0316;0.0149;0.471;0.0106;0.488;Dy_auto
5;0.0464;0.0178;0.384;0.0155;0.585;Dy_auto
6;0.0681;0.0171;0.251;0.0227;0.561;Dy_auto
7;0.1;0.019;0.19;0.0334;0.624;Dy_auto
8;0.147;0.0186;0.127;0.049;0.61;Dy_auto
9;0.215;0.0208;0.0965;0.0719;0.681;Dy_auto
10;0.316;0.0182;0.0575;0.106;0.596;Dy_auto
11;0.464;0.0174;0.0374;0.155;0.569;Dy_auto
12;0.681;0.0282;0.0415;0.227;0.925;Dy_auto
13;1;0.0235;0.0235;0.334;0.769;Dy_auto
14;1.47;0.0303;0.0206;0.49;0.991;Dy_auto
15;2.15;0.0375;0.0174;0.719;1.23;Dy_auto
16;3.16;0.053;0.0167;1.06;1.73;Dy_auto
17;4.64;0.0698;0.015;1.55;2.29;Dy_auto
18;6.81;0.0947;0.0139;2.27;3.1;Dy_auto
19;10;0.13;0.013;3.34;4.25;Dy_auto
20;14.7;0.176;0.012;4.9;5.77;Dy_auto
21;21.5;0.239;0.0111;7.19;7.84;Dy_auto
22;31.6;0.324;0.0103;10.6;10.6;Dy_auto
23;46.4;0.439;0.00946;15.5;14.4;Dy_auto
24;68.1;0.593;0.00871;22.7;19.4;Dy_auto
25;100;0.798;0.00798;33.4;26.1;Dy_auto
26;147;1.07;0.00732;49;35.2;Dy_auto
27;215;1.45;0.00671;71.9;47.4;Dy_auto
28;316;1.95;0.00616;106;63.8;Dy_auto
29;464;2.62;0.00565;155;86;Dy_auto
30;681;3.58;0.00526;227;117;Dy_auto
31;1000;4.98;0.00498;334;163;Dy_auto

Data Series Information
Name:;;;3-2 1
Number of Intervals:;;;1
Application:;;;RHEOPLUS/32 V3.61 21006227-33024
Device:;;;MCR302 SN81156610; FW3.65; Slot(9,-1)
Measuring Date/Time:;;;2023/09/19; 22:16
Measuring System:;;;CP50-2-SN42594; d=0.206 mm
Accessories:;;;TU1=P-PTD200-SN81263554

Interval:;;;1
Number of Data Points:;;;1

Time Setting:;;;31 Meas. Pts.
;;;Meas. Pt. Duration 60 ... 5 s log
Measuring Profile:
  Shear Rate;;;d(gamma)/dt = 0.01 ... 1000 1/s log; |Slope| = 6 Pt. / dec

Meas. Pts.;Shear Rate;Shear Stress;Viscosity;Speed;Torque;Status
;[1/s];[Pa];[Pa�Es];[1/min];[��Nm];[]
1;0.01;-0.000486;-0.0487;0.00334;-0.0159;Dy_auto

Data Series Information
Name:;;;3-2 2
Number of Intervals:;;;1
Application:;;;RHEOPLUS/32 V3.61 21006227-33024
Device:;;;MCR302 SN81156610; FW3.65; Slot(9,-1)
Measuring Date/Time:;;;2023/09/19; 22:18
Measuring System:;;;CP50-2-SN42594; d=0.206 mm
Accessories:;;;TU1=P-PTD200-SN81263554

Interval:;;;1
Number of Data Points:;;;5

Time Setting:;;;31 Meas. Pts.
;;;Meas. Pt. Duration 60 ... 5 s log
Measuring Profile:
  Shear Rate;;;d(gamma)/dt = 0.01 ... 1000 1/s log; |Slope| = 6 Pt. / dec

Meas. Pts.;Shear Rate;Shear Stress;Viscosity;Speed;Torque;Status
;[1/s];[Pa];[Pa�Es];[1/min];[��Nm];[]
1;0.01;-0.000783;-0.0783;0.00334;-0.0257;Dy_auto
2;0.0147;-0.000364;-0.0248;0.0049;-0.0119;Dy_auto
3;0.0215;-0.00032;-0.0149;0.00719;-0.0105;Dy_auto
4;0.0316;0.00027;0.00853;0.0106;0.00884;M- ,Dy_
5;0.0464;0.0000246;0.00053;0.0155;0.000807;M- ,Dy_

Data Series Information
Name:;;;3-2 3
Number of Intervals:;;;1
Application:;;;RHEOPLUS/32 V3.61 21006227-33024
Device:;;;MCR302 SN81156610; FW3.65; Slot(9,-1)
Measuring Date/Time:;;;2023/09/19; 22:24
Measuring System:;;;CP50-2-SN42594; d=0.206 mm
Accessories:;;;TU1=P-PTD200-SN81263554

Interval:;;;1
Number of Data Points:;;;31

Time Setting:;;;31 Meas. Pts.
;;;Meas. Pt. Duration 60 ... 5 s log
Measuring Profile:
  Shear Rate;;;d(gamma)/dt = 0.01 ... 1000 1/s log; |Slope| = 6 Pt. / dec

Meas. Pts.;Shear Rate;Shear Stress;Viscosity;Speed;Torque;Status
;[1/s];[Pa];[Pa�Es];[1/min];[��Nm];[]
1;0.01;-0.000411;-0.0411;0.00334;-0.0135;Dy_auto
2;0.0147;-0.000254;-0.0173;0.0049;-0.00833;M- ,Dy_
3;0.0215;0.000564;0.0262;0.00719;0.0185;Dy_auto
4;0.0316;0.000689;0.0218;0.0106;0.0226;Dy_auto
5;0.0464;0.000606;0.0131;0.0155;0.0199;Dy_auto
6;0.0681;0.000784;0.0115;0.0227;0.0257;Dy_auto
7;0.1;0.000875;0.00875;0.0334;0.0287;Dy_auto
8;0.147;0.00234;0.016;0.049;0.0768;Dy_auto
9;0.215;0.00301;0.014;0.0719;0.0988;Dy_auto
10;0.316;0.00429;0.0136;0.106;0.141;Dy_auto
11;0.464;0.00635;0.0137;0.155;0.208;Dy_auto
12;0.681;0.0101;0.0149;0.227;0.332;Dy_auto
13;1;0.0155;0.0155;0.334;0.508;Dy_auto
14;1.47;0.0231;0.0157;0.49;0.756;Dy_auto
15;2.15;0.0325;0.0151;0.719;1.06;Dy_auto
16;3.16;0.0447;0.0141;1.06;1.46;Dy_auto
17;4.64;0.0639;0.0138;1.55;2.09;Dy_auto
18;6.81;0.0888;0.013;2.27;2.91;Dy_auto
19;10;0.125;0.0125;3.34;4.09;Dy_auto
20;14.7;0.172;0.0117;4.9;5.64;Dy_auto
21;21.5;0.235;0.0109;7.19;7.71;Dy_auto
22;31.6;0.321;0.0102;10.6;10.5;Dy_auto
23;46.4;0.436;0.00939;15.5;14.3;Dy_auto
24;68.1;0.59;0.00866;22.7;19.3;Dy_auto
25;100;0.794;0.00794;33.4;26;Dy_auto
26;147;1.07;0.0073;49;35.1;Dy_auto
27;215;1.44;0.0067;71.9;47.3;Dy_auto
28;316;1.94;0.00614;106;63.7;Dy_auto
29;464;2.62;0.00564;155;85.7;Dy_auto
30;681;3.57;0.00525;227;117;Dy_auto
31;1000;4.96;0.00496;334;163;Dy_auto

Data Series Information
Name:;;;3-3 1
Number of Intervals:;;;1
Application:;;;RHEOPLUS/32 V3.61 21006227-33024
Device:;;;MCR302 SN81156610; FW3.65; Slot(9,-1)
Measuring Date/Time:;;;2023/09/19; 22:40
Measuring System:;;;CP50-2-SN42594; d=0.206 mm
Accessories:;;;TU1=P-PTD200-SN81263554

Interval:;;;1
Number of Data Points:;;;31

Time Setting:;;;31 Meas. Pts.
;;;Meas. Pt. Duration 60 ... 5 s log
Measuring Profile:
  Shear Rate;;;d(gamma)/dt = 0.01 ... 1000 1/s log; |Slope| = 6 Pt. / dec

Meas. Pts.;Shear Rate;Shear Stress;Viscosity;Speed;Torque;Status
;[1/s];[Pa];[Pa�Es];[1/min];[��Nm];[]
1;0.01;-0.000358;-0.0359;0.00334;-0.0117;Dy_auto
2;0.0147;-0.000594;-0.0405;0.0049;-0.0195;Dy_auto
3;0.0215;-0.000105;-0.00489;0.00719;-0.00345;M- ,Dy_
4;0.0316;-0.0000537;-0.0017;0.0106;-0.00176;M- ,Dy_
5;0.0464;-0.000103;-0.00221;0.0155;-0.00336;M- ,Dy_
6;0.0681;-0.0000319;-0.000468;0.0227;-0.00105;M- ,Dy_
7;0.1;0.000281;0.00281;0.0334;0.0092;M- ,Dy_
8;0.147;0.00148;0.0101;0.049;0.0484;Dy_auto
9;0.215;0.00235;0.0109;0.0719;0.0769;Dy_auto
10;0.316;0.00359;0.0113;0.106;0.117;Dy_auto
11;0.464;0.00581;0.0125;0.155;0.19;Dy_auto
12;0.681;0.00905;0.0133;0.227;0.297;Dy_auto
13;1;0.0141;0.0141;0.334;0.463;Dy_auto
14;1.47;0.021;0.0143;0.49;0.689;Dy_auto
15;2.15;0.0303;0.0141;0.719;0.993;Dy_auto
16;3.16;0.0419;0.0133;1.06;1.37;Dy_auto
17;4.64;0.0601;0.013;1.55;1.97;Dy_auto
18;6.81;0.0844;0.0124;2.27;2.77;Dy_auto
19;10;0.119;0.0119;3.34;3.89;Dy_auto
20;14.7;0.164;0.0112;4.9;5.37;Dy_auto
21;21.5;0.225;0.0104;7.19;7.36;Dy_auto
22;31.6;0.307;0.00971;10.6;10.1;Dy_auto
23;46.4;0.418;0.009;15.5;13.7;Dy_auto
24;68.1;0.568;0.00833;22.7;18.6;Dy_auto
25;100;0.765;0.00765;33.4;25.1;Dy_auto
26;147;1.03;0.00704;49;33.8;Dy_auto
27;215;1.39;0.00646;71.9;45.6;Dy_auto
28;316;1.88;0.00594;106;61.5;Dy_auto
29;464;2.53;0.00545;155;82.9;Dy_auto
30;681;3.46;0.00508;227;113;Dy_auto
31;1000;4.8;0.0048;334;157;Dy_auto